Workbook

Sheet ACCUEIL
A1: EQUIPE DE FRANCE U19 FUTSAL - TABLEAU DE BORD
B5: MATCHS | D5: VICTOIRES | F5: NULS | H5: DÉFAITES | J5: BUTS FR | L5: BUTS ADV | N5: DIFF
B6: 4 | D6: 1 | F6: 1 | H6: 2 | J6: 15 | L6: 18 | N6: -3
B9: RÉSULTATS DES MATCHS
B10: Match | C10: Adversaire | D10: Lieu | E10: FRA | F10: ADV | G10: Résultat | H10: Diff | J10: TOP BUTEURS | K10: Buts | M10: TOP PASSEURS | N10: PD
B11: Match 1 | C11: Croatie | D11: Croatie | E11: 5 | F11: 3 | G11: Victoire | H11: 2 | J11: L. LADIRE | K11: 3 | M11: F. SIMIAND | N11: 3
B12: Match 1 | C12: Croatie | D12: Croatie | E12: 3 | F12: 3 | G12: Nul | H12: 0 | J12: L. RAHO MOUSSA | K12: 3 | M12: T. FERREIRA | N12: 2
B13: Match 2 | C13: Portugal | D13: France | E13: 4 | F13: 6 | G13: Défaite | H13: -2 | J13: O. KAMISSOKO | K13: 2 | M13: S. AGUENGUI | N13: 2
B14: Match 2 | C14: Portugal | D14: France | E14: 3 | F14: 6 | G14: Défaite | H14: -3 | J14: E. MOHAMED | K14: 2 | M14: L. LADIRE | N14: 1
J15: T. FERREIRA | K15: 1 | M15: O. KAMISSOKO | N15: 1
J17: TOP TIREURS | K17: Tirs | M17: TOP REC+INT | N17: Total
J18: F. SIMIAND | K18: 29 | M18: L. LADIRE | N18: 23
J19: L. RAHO MOUSSA | K19: 22 | M19: I. BERRADA | N19: 15
J20: L. LADIRE | K20: 21 | M20: O. KAMISSOKO | N20: 13
J21: E. MOHAMED | K21: 20 | M21: F. SIMIAND | N21: 13
J22: T. FERREIRA | K22: 19 | M22: T. FERREIRA | N22: 12

Sheet LEGENDE
A1: Abréviation | B1: Signification
A2: N | B2: Numéro de maillot
A3: Min. | B3: Minutes jouées
A4: PD | B4: Passes décisives
A5: B+PD | B5: Buts + Passes décisives
A6: T.Cad | B6: Tirs cadrés
A7: %Cad | B7: Pourcentage de tirs cadrés
A8: Int. | B8: Interceptions
A9: Rec. | B9: Récupérations
A10: D.OFF G | B10: Duels offensifs gagnés
A11: D.OFF T | B11: Duels offensifs tentés
A12: %D.OFF | B12: Pourcentage de duels offensifs gagnés
... A36: Rec_adv | B36: Récupérations adverses

Sheet EQUIPE
A1: SYNTHÈSE ÉQUIPE - JOUEURS DE CHAMP
A4: Joueur | B4: N | C4: Poste | D4: Matchs | E4: Min. | F4: Buts | G4: PD | H4: B+PD | I4: Tirs | J4: T.Cad | K4: %Cad | L4: Int. | M4: Rec. | N4: Pertes | O4: D.OFF G | P4: D.OFF T | Q4: %D.OFF | R4: D.DEF G | S4: D.DEF T | T4: %D.DEF
A5: L. LADIRE | B5: 8 | C5: Meneur | D5: 4 | E5: 64.1 | F5: 3 | G5: 1 | H5: 4 | I5: 21 | J5: 12 | K5: 0.57142857 | L5: 12 | M5: 11 | N5: 30 | O5: 8 | P5: 13 | Q5: 0.61538462 | R5: 4 | S5: 6 | T5: 0.66666667
A6: T. FERREIRA | B6: 3 | C6: Meneur | D6: 4 | E6: 41.7 | F6: 1 | G6: 2 | H6: 3 | I6: 19 | J6: 7 | K6: 0.36842105 | L6: 8 | M6: 4 | N6: 23 | O6: 2 | P6: 4 | Q6: 0.5 | R6: 0 | S6: 2 | T6: 0
A7: O. KAMISSOKO | B7: 5 | C7: Ailier | D7: 4 | E7: 41.9 | F7: 2 | G7: 1 | H7: 3 | I7: 6 | J7: 4 | K7: 0.66666667 | L7: 8 | M7: 5 | N7: 29 | O7: 10 | P7: 20 | Q7: 0.5 | R7: 5 | S7: 6 | T7: 0.83333333
A8: F. SIMIAND | B8: 11 | C8: Ailier | D8: 4 | E8: 69.1 | F8: 0 | G8: 3 | H8: 3 | I8: 29 | J8: 14 | K8: 0.48275862 | L8: 8 | M8: 5 | N8: 38 | O8: 2 | P8: 10 | Q8: 0.2 | R8: 4 | S8: 9 | T8: 0.44444444
A9: I. BERRADA | B9: 10 | C9: Meneur côté | D9: 4 | E9: 60.4 | F9: 0 | G9: 1 | H9: 1 | I9: 8 | J9: 3 | K9: 0.375 | L9: 10 | M9: 5 | N9: 26 | O9: 1 | P9: 9 | Q9: 0.11111111 | R9: 1 | S9: 5 | T9: 0.2
A10: Z. CHAKRI | B10: 14 | C10: Pivot | D10: 4 | E10: 54.5 | F10: 1 | G10: 0 | H10: 1 | I10: 9 | J10: 4 | K10: 0.44444444 | L10: 3 | M10: 7 | N10: 13 | O10: 1 | P10: 2 | Q10: 0.5 | R10: 2 | S10: 3 | T10: 0.66666667
A11: E. MOHAMED | B11: 6 | C11: Meneur | D11: 2 | E11: 36 | F11: 2 | G11: 1 | H11: 3 | I11: 20 | J11: 9 | K11: 0.45 | L11: 8 | M11: 1 | N11: 16 | O11: 8 | P11: 14 | Q11: 0.57142857 | R11: 6 | S11: 9 | T11: 0.66666667
A12: L. RAHO MOUSSA | B12: 9 | C12: Ailier | D12: 2 | E12: 32.5 | F12: 3 | G12: 0 | H12: 3 | I12: 22 | J12: 12 | K12: 0.54545455 | L12: 2 | M12: 2 | N12: 13 | O12: 12 | P12: 13 | Q12: 0.92307692 | R12: 0 | S12: 0 | T12: -
A13: H. BRAGUE | B13: 2 | C13: Ailier | D13: 2 | E13: 26 | F13: 1 | G13: 1 | H13: 2 | I13: 8 | J13: 4 | K13: 0.5 | L13: 3 | M13: 1 | N13: 8 | O13: 3 | P13: 7 | Q13: 0.42857143 | R13: 1 | S13: 4 | T13: 0.25
A14: S. AGUENGUI | B14: 4 | C14: Pivot | D14: 2 | E14: 18.4 | F14: 0 | G14: 2 | H14: 2 | I14: 0 | J14: 0 | K14: - | L14: 2 | M14: 0 | N14: 6 | O14: 0 | P14: 2 | Q14: 0 | R14: 3 | S14: 4 | T14: 0.75
A15: S. CARFACHE | B15: 6 | C15: Meneur | D15: 2 | E15: 21.5 | F15: 0 | G15: 1 | H15: 1 | I15: 5 | J15: 1 | K15: 0.2 | L15: 0 | M15: 3 | N15: 11 | O15: 2 | P15: 3 | Q15: 0.66666667 | R15: 4 | S15: 4 | T15: 1
A16: K. DA ROCHA | B16: 7 | C16: Meneur côté | D16: 2 | E16: 26.5 | F16: 1 | G16: 0 | H16: 1 | I16: 10 | J16: 7 | K16: 0.7 | L16: 2 | M16: 3 | N16: 5 | O16: 0 | P16: 1 | Q16: 0 | R16: 0 | S16: 0 | T16: -
A17: S. LALAYMIA | B17: 13 | C17: Meneur côté | D17: 2 | E17: 27.6 | F17: 1 | G17: 0 | H17: 1 | I17: 5 | J17: 2 | K17: 0.4 | L17: 2 | M17: 2 | N17: 12 | O17: 0 | P17: 2 | Q17: 0 | R17: 5 | S17: 7 | T17: 0.71428571
A18: F. BADAD | B18: 17 | C18: Meneur côté | D18: 2 | E18: 20.6 | F18: 1 | G18: 0 | H18: 1 | I18: 2 | J18: 2 | K18: 1 | L18: 2 | M18: 2 | N18: 13 | O18: 0 | P18: 4 | Q18: 0 | R18: 2 | S18: 4 | T18: 0.5
A19: R. HOUMADI | B19: 2 | C19: Meneur | D19: 2 | E19: 11.9 | F19: 0 | G19: 0 | H19: 0 | I19: 0 | J19: 0 | K19: - | L19: 0 | M19: 1 | N19: 2 | O19: 0 | P19: 0 | Q19: - | R19: 0 | S19: 0 | T19: -
A20: R. SNOUSSI | B20: 7 | C20: Pivot | D20: 2 | E20: 26.1 | F20: 0 | G20: 0 | H20: 0 | I20: 8 | J20: 1 | K20: 0.125 | L20: 2 | M20: 6 | N20: 11 | O20: 1 | P20: 2 | Q20: 0.5 | R20: 1 | S20: 2 | T20: 0.5
A21: A. HENRY | B21: 9 | C21: Ailier | D21: 2 | E21: 18.9 | F21: 0 | G21: 0 | H21: 0 | I21: 4 | J21: 1 | K21: 0.25 | L21: 0 | M21: 1 | N21: 10 | O21: 3 | P21: 7 | Q21: 0.42857143 | R21: 4 | S21: 4 | T21: 1
A22: M. TRAORE | B22: 13 | C22: Pivot | D22: 2 | E22: 23.5 | F22: 0 | G22: 0 | H22: 0 | I22: 10 | J22: 5 | K22: 0.5 | L22: 0 | M22: 2 | N22: 4 | O22: 1 | P22: 1 | Q22: 1 | R22: 3 | S22: 3 | T22: 1
A23: Y. EL KAIM BILLAH | B23: 4 | C23: Pivot | D23: 1 | E23: 10.5 | F23: 0 | G23: 1 | H23: 1 | I23: 2 | J23: 0 | K23: 0 | L23: 0 | M23: 0 | N23: 2 | O23: 0 | P23: 1 | Q23: 0 | R23: 0 | S23: 0 | T23: -

Sheet FICHE JOUEUR
A1: FICHE INDIVIDUELLE JOUEUR | O1: Joueur | P1: Poste | Q1: Numero | R1: Matchs | S1: Minutes | T1: Buts | U1: PD | V1: Tirs | W1: Tirs_cadres | X1: Interceptions | Y1: Recuperations | Z1: Pertes | AA1: D_OFF_G | AB1: D_OFF_T | AC1: D_DEF_G | AD1: D_DEF_T | AE1: Pct_TC | AF1: Pct_DO | AG1: Pct_DD
O2: L. LADIRE | P2: Meneur | Q2: 8 | R2: 4 | S2: 64.1 | T2: 3 | U2: 1 | V2: 21 | W2: 12 | X2: 12 | Y2: 11 | Z2: 30 | AA2: 8 | AB2: 13 | AC2: 4 | AD2: 6 | AE2: 0.57142857 | AF2: 0.61538462 | AG2: 0.66666667
O3: T. FERREIRA | P3: Meneur | Q3: 3 | R3: 4 | S3: 41.7 | T3: 1 | U3: 2 | V3: 19 | W3: 7 | X3: 8 | Y3: 4 | Z3: 23 | AA3: 2 | AB3: 4 | AC3: 0 | AD3: 2 | AE3: 0.36842105 | AF3: 0.5 | AG3: 0
O4: O. KAMISSOKO | P4: Ailier | Q4: 5 | R4: 4 | S4: 41.9 | T4: 2 | U4: 1 | V4: 6 | W4: 4 | X4: 8 | Y4: 5 | Z4: 29 | AA4: 10 | AB4: 20 | AC4: 5 | AD4: 6 | AE4: 0.66666667 | AF4: 0.5 | AG4: 0.83333333
B5: SELECTIONNER : | D5: O. KAMISSOKO | O5: E. MOHAMED | P5: Meneur | Q5: 6 | R5: 2 | S5: 36 | T5: 2 | U5: 1 | V5: 20 | W5: 9 | X5: 8 | Y5: 1 | Z5: 16 | AA5: 8 | AB5: 14 | AC5: 6 | AD5: 9 | AE5: 0.45 | AF5: 0.57142857 | AG5: 0.66666667
O6: L. RAHO MOUSSA | P6: Ailier | Q6: 9 | R6: 2 | S6: 32.5 | T6: 3 | U6: 0 | V6: 22 | W6: 12 | X6: 2 | Y6: 2 | Z6: 13 | AA6: 12 | AB6: 13 | AC6: 0 | AD6: 0 | AE6: 0.54545455 | AF6: 0.92307692 | AG6: 0
B7: Poste | C7: =IFERROR(VLOOKUP($D$5,$O$1:$AG$20,2,FALSE()),"-") -> Ailier | O7: F. SIMIAND | P7: Ailier | Q7: 11 | R7: 4 | S7: 69.1 | T7: 0 | U7: 3 | V7: 29 | W7: 14 | X7: 8 | Y7: 5 | Z7: 38 | AA7: 2 | AB7: 10 | AC7: 4 | AD7: 9 | AE7: 0.48275862 | AF7: 0.2 | AG7: 0.44444444
B8: Numero | C8: =IFERROR(VLOOKUP($D$5,$O$1:$AG$20,3,FALSE()),"-") -> 5 | O8: H. BRAGUE | P8: Ailier | Q8: 2 | R8: 2 | S8: 26 | T8: 1 | U8: 1 | V8: 8 | W8: 4 | X8: 3 | Y8: 1 | Z8: 8 | AA8: 3 | AB8: 7 | AC8: 1 | AD8: 4 | AE8: 0.5 | AF8: 0.42857143 | AG8: 0.25
B9: Matchs | C9: =IFERROR(VLOOKUP($D$5,$O$1:$AG$20,4,FALSE()),"-") -> 4 | O9: S. AGUENGUI | P9: Pivot | Q9: 4 | R9: 2 | S9: 18.4 | T9: 0 | U9: 2 | V9: 0 | W9: 0 | X9: 2 | Y9: 0 | Z9: 6 | AA9: 0 | AB9: 2 | AC9: 3 | AD9: 4 | AE9: 0 | AF9: 0 | AG9: 0.75
B10: Minutes | C10: =IFERROR(VLOOKUP($D$5,$O$1:$AG$20,5,FALSE()),"-") -> 41.9 | O10: Y. EL KAIM BILLAH | P10: Pivot | Q10: 4 | R10: 1 | S10: 10.5 | T10: 0 | U10: 1 | V10: 2 | W10: 0 | X10: 0 | Y10: 0 | Z10: 2 | AA10: 0 | AB10: 1 | AC10: 0 | AD10: 0 | AE10: 0 | AF10: 0 | AG10: 0
O11: S. CARFACHE | P11: Meneur | Q11: 6 | R11: 2 | S11: 21.5 | T11: 0 | U11: 1 | V11: 5 | W11: 1 | X11: 0 | Y11: 3 | Z11: 11 | AA11: 2 | AB11: 3 | AC11: 4 | AD11: 4 | AE11: 0.2 | AF11: 0.66666667 | AG11: 1
B12: CONTRIBUTION OFFENSIVE | O12: K. DA ROCHA | P12: Meneur côté | Q12: 7 | R12: 2 | S12: 26.5 | T12: 1 | U12: 0 | V12: 10 | W12: 7 | X12: 2 | Y12: 3 | Z12: 5 | AA12: 0 | AB12: 1 | AC12: 0 | AD12: 0 | AE12: 0.7 | AF12: 0 | AG12: 0
B13: Buts | C13: =IFERROR(VLOOKUP($D$5,$O$1:$AG$20,6,FALSE()),"-") -> 2 | O13: I. BERRADA | P13: Meneur côté | Q13: 10 | R13: 4 | S13: 60.4 | T13: 0 | U13: 1 | V13: 8 | W13: 3 | X13: 10 | Y13: 5 | Z13: 26 | AA13: 1 | AB13: 9 | AC13: 1 | AD13: 5 | AE13: 0.375 | AF13: 0.11111111 | AG13: 0.2
B14: Passes dec. | C14: =IFERROR(VLOOKUP($D$5,$O$1:$AG$20,7,FALSE()),"-") -> 1 | O14: S. LALAYMIA | P14: Meneur côté | Q14: 13 | R14: 2 | S14: 27.6 | T14: 1 | U14: 0 | V14: 5 | W14: 2 | X14: 2 | Y14: 2 | Z14: 12 | AA14: 0 | AB14: 2 | AC14: 5 | AD14: 7 | AE14: 0.4 | AF14: 0 | AG14: 0.71428571
B15: Tirs | C15: =IFERROR(VLOOKUP($D$5,$O$1:$AG$20,8,FALSE()),"-") -> 6 | O15: Z. CHAKRI | P15: Pivot | Q15: 14 | R15: 4 | S15: 54.5 | T15: 1 | U15: 0 | V15: 9 | W15: 4 | X15: 3 | Y15: 7 | Z15: 13 | AA15: 1 | AB15: 2 | AC15: 2 | AD15: 3 | AE15: 0.44444444 | AF15: 0.5 | AG15: 0.66666667
B16: Tirs cadres | C16: =IFERROR(VLOOKUP($D$5,$O$1:$AG$20,9,FALSE()),"-") -> 4 | O16: F. BADAD | P16: Meneur côté | Q16: 17 | R16: 2 | S16: 20.6 | T16: 1 | U16: 0 | V16: 2 | W16: 2 | X16: 2 | Y16: 2 | Z16: 13 | AA16: 0 | AB16: 4 | AC16: 2 | AD16: 4 | AE16: 1 | AF16: 0 | AG16: 0.5
B17: % Tirs cad. | C17: =IFERROR(VLOOKUP($D$5,$O$1:$AG$20,17,FALSE()),"-") -> 0.66666667 | O17: R. HOUMADI | P17: Meneur | Q17: 2 | R17: 2 | S17: 11.9 | T17: 0 | U17: 0 | V17: 0 | W17: 0 | X17: 0 | Y17: 1 | Z17: 2 | AA17: 0 | AB17: 0 | AC17: 0 | AD17: 0 | AE17: 0 | AF17: 0 | AG17: 0
O18: R. SNOUSSI | P18: Pivot | Q18: 7 | R18: 2 | S18: 26.1 | T18: 0 | U18: 0 | V18: 8 | W18: 1 | X18: 2 | Y18: 6 | Z18: 11 | AA18: 1 | AB18: 2 | AC18: 1 | AD18: 2 | AE18: 0.125 | AF18: 0.5 | AG18: 0.5
B19: CONTRIBUTION DEFENSIVE | O19: A. HENRY | P19: Ailier | Q19: 9 | R19: 2 | S19: 18.9 | T19: 0 | U19: 0 | V19: 4 | W19: 1 | X19: 0 | Y19: 1 | Z19: 10 | AA19: 3 | AB19: 7 | AC19: 4 | AD19: 4 | AE19: 0.25 | AF19: 0.42857143 | AG19: 1
B20: Interceptions | C20: =IFERROR(VLOOKUP($D$5,$O$1:$AG$20,10,FALSE()),"-") -> 8 | O20: M. TRAORE | P20: Pivot | Q20: 13 | R20: 2 | S20: 23.5 | T20: 0 | U20: 0 | V20: 10 | W20: 5 | X20: 0 | Y20: 2 | Z20: 4 | AA20: 1 | AB20: 1 | AC20: 3 | AD20: 3 | AE20: 0.5 | AF20: 1 | AG20: 1
B21: Récupérations | C21: =IFERROR(VLOOKUP($D$5,$O$1:$AG$20,11,FALSE()),"-") -> 5
B22: Pertes | C22: =IFERROR(VLOOKUP($D$5,$O$1:$AG$20,12,FALSE()),"-") -> 29
B23: D.OFF gagnes | C23: =IFERROR(VLOOKUP($D$5,$O$1:$AG$20,13,FALSE()),"-") -> 10
B24: D.OFF tentes | C24: =IFERROR(VLOOKUP($D$5,$O$1:$AG$20,14,FALSE()),"-") -> 20
B25: D.DEF gagnes | C25: =IFERROR(VLOOKUP($D$5,$O$1:$AG$20,15,FALSE()),"-") -> 5
B26: D.DEF tentes | C26: =IFERROR(VLOOKUP($D$5,$O$1:$AG$20,16,FALSE()),"-") -> 6
B27: % D.OFF | C27: =IFERROR(VLOOKUP($D$5,$O$1:$AG$20,18,FALSE()),"-") -> 0.5
B28: % D.DEF | C28: =IFERROR(VLOOKUP($D$5,$O$1:$AG$20,19,FALSE()),"-") -> 0.83333333
B32: Stat | C32: Joueur | D32: Moy. Equipe
B33: Buts | C33: =IFERROR(VLOOKUP($D$5,$O$1:$AG$20,6,FALSE()),0) -> 2 | D33: 0.8
B34: PD | C34: =IFERROR(VLOOKUP($D$5,$O$1:$AG$20,7,FALSE()),0) -> 1 | D34: 0.7
B35: Tirs | C35: =IFERROR(VLOOKUP($D$5,$O$1:$AG$20,8,FALSE()),0) -> 6 | D35: 9.9
B36: Int. | C36: =IFERROR(VLOOKUP($D$5,$O$1:$AG$20,10,FALSE()),0) -> 8 | D36: 3.8
B37: Rec. | C37: =IFERROR(VLOOKUP($D$5,$O$1:$AG$20,11,FALSE()),0) -> 5 | D37: 3.2
B38: Pertes | C38: =IFERROR(VLOOKUP($D$5,$O$1:$AG$20,12,FALSE()),0) -> 29 | D38: 14.3

Sheet MATCHS
A1: ANALYSE PAR MATCH
A5: FRANCE 5 - 3 CROATIE (Croatie) - VICTOIRE
A6: Joueur | B6: N | C6: Poste | D6: Temps | E6: Buts | F6: PD | G6: Tirs | H6: T.Cad | I6: Int. | J6: Rec. | K6: Pertes | L6: D.OFF G/T | M6: D.DEF G/T | N6: Fautes C. | O6: Fautes S. | P6: Err.T. | Q6: Pass.L. | R6: Ball.R.
A7: F. SIMIAND | B7: 11 | C7: Ailier | D7: 23'00 | E7: 0 | F7: 1 | G7: 9 | H7: 6 | I7: 3 | J7: 2 | K7: 16 | L7: 1/2 | M7: 3/4 | N7: 0 | O7: 0 | P7: 1 | Q7: 6 | R7: 1
A8: L. LADIRE | B8: 8 | C8: Meneur | D8: 17'30 | E8: 1 | F8: 0 | G8: 4 | H8: 3 | I8: 1 | J8: 4 | K8: 5 | L8: 3/4 | M8: 1/3 | N8: 1 | O8: 3 | P8: 1 | Q8: 2 | R8: 1
A9: H. BRAGUE | B9: 2 | C9: Ailier | D9: 16'00 | E9: 1 | F9: 1 | G9: 4 | H9: 2 | I9: 2 | J9: 1 | K9: 6 | L9: 1/3 | M9: 1/2 | N9: 0 | O9: 0 | P9: 0 | Q9: 4 | R9: 0
A10: K. DA ROCHA | B10: 7 | C10: Meneur côté | D10: 14'30 | E10: 1 | F10: 0 | G10: 7 | H10: 5 | I10: 1 | J10: 2 | K10: 4 | L10: 0/1 | M10: 0/0 | N10: 2 | O10: 0 | P10: 0 | Q10: 2 | R10: 0
A11: L. RAHO MOUSSA | B11: 9 | C11: Ailier | D11: 14'30 | E11: 1 | F11: 0 | G11: 7 | H11: 4 | I11: 0 | J11: 1 | K11: 4 | L11: 9/9 | M11: 0/0 | N11: 1 | O11: 2 | P11: 0 | Q11: 0 | R11: 0
A12: I. BERRADA | B12: 10 | C12: Meneur côté | D12: 14'00 | E12: 0 | F12: 0 | G12: 1 | H12: 0 | I12: 2 | J12: 1 | K12: 3 | L12: 0/1 | M12: 0/0 | N12: 0 | O12: 0 | P12: 2 | Q12: 1 | R12: 0
A13: Z. CHAKRI | B13: 14 | C13: Pivot | D13: 14'00 | E13: 0 | F13: 0 | G13: 2 | H13: 1 | I13: 0 | J13: 3 | K13: 3 | L13: 0/0 | M13: 0/0 | N13: 0 | O13: 0 | P13: 1 | Q13: 1 | R13: 0
A14: M. TRAORE | B14: 13 | C14: Pivot | D14: 12'40 | E14: 0 | F14: 0 | G14: 5 | H14: 4 | I14: 0 | J14: 2 | K14: 2 | L14: 1/1 | M14: 3/3 | N14: 0 | O14: 0 | P14: 1 | Q14: 1 | R14: 0
A15: S. CARFACHE | B15: 6 | C15: Meneur | D15: 12'00 | E15: 0 | F15: 1 | G15: 2 | H15: 0 | I15: 0 | J15: 1 | K15: 7 | L15: 1/1 | M15: 1/1 | N15: 0 | O15: 2 | P15: 0 | Q15: 4 | R15: 0
A16: T. FERREIRA | B16: 3 | C16: Meneur | D16: 11'00 | E16: 0 | F16: 0 | G16: 3 | H16: 1 | I16: 2 | J16: 1 | K16: 2 | L16: 1/1 | M16: 0/1 | N16: 2 | O16: 0 | P16: 0 | Q16: 0 | R16: 0
A17: O. KAMISSOKO | B17: 5 | C17: Ailier | D17: 9'00 | E17: 1 | F17: 1 | G17: 1 | H17: 1 | I17: 0 | J17: 1 | K17: 8 | L17: 4/9 | M17: 1/1 | N17: 1 | O17: 1 | P17: 0 | Q17: 0 | R17: 0
A18: GARDIEN
A19: Gardien | B19: Temps | C19: Arrets | D19: Buts enc. | E19: Rel.F R | F19: Rel.F L | G19: Rel.D R | H19: Rel.D L | I19: % Rel. | J19: Pertes
A20: M. VALVERDE | B20: 39' | C20: 13 | D20: 3 | E20: 21 | F20: 0 | G20: 6 | H20: 5 | I20: 0.84375 | J20: 4
A23: FRANCE 3 - 3 CROATIE (Croatie) - NUL
A24: Joueur | B24: N | C24: Poste | D24: Temps | E24: Buts | F24: PD | G24: Tirs | H24: T.Cad | I24: Int. | J24: Rec. | K24: Pertes | L24: D.OFF G/T | M24: D.DEF G/T | N24: Fautes C. | O24: Fautes S. | P24: Err.T. | Q24: Pass.L. | R24: Ball.R.
A25: E. MOHAMED | B25: 6 | C25: Meneur | D25: 18'30 | E25: 2 | F25: 1 | G25: 12 | H25: 6 | I25: 3 | J25: 0 | K25: 5 | L25: 5/7 | M25: 2/3 | N25: 1 | O25: 2 | P25: 2 | Q25: 1 | R25: 0
A26: F. SIMIAND | B26: 11 | C26: Ailier | D26: 16'23 | E26: 0 | F26: 1 | G26: 7 | H26: 4 | I26: 1 | J26: 2 | K26: 7 | L26: 1/6 | M26: 0/2 | N26: 0 | O26: 0 | P26: 0 | Q26: 3 | R26: 0
A27: S. LALAYMIA | B27: 13 | C27: Meneur côté | D27: 13'50 | E27: 1 | F27: 0 | G27: 3 | H27: 1 | I27: 2 | J27: 2 | K27: 8 | L27: 0/1 | M27: 2/3 | N27: 0 | O27: 1 | P27: 1 | Q27: 2 | R27: 1
A28: L. LADIRE | B28: 8 | C28: Meneur | D28: 13'30 | E28: 0 | F28: 0 | G28: 4 | H28: 3 | I28: 5 | J28: 5 | K28: 7 | L28: 2/3 | M28: 1/1 | N28: 2 | O28: 2 | P28: 1 | Q28: 1 | R28: 0
A29: Z. CHAKRI | B29: 14 | C29: Pivot | D29: 13'10 | E29: 1 | F29: 0 | G29: 3 | H29: 1 | I29: 1 | J29: 0 | K29: 3 | L29: 0/1 | M29: 0/1 | N29: 0 | O29: 0 | P29: 2 | Q29: 1 | R29: 0
A30: R. SNOUSSI | B30: 7 | C30: Pivot | D30: 12' | E30: 0 | F30: 0 | G30: 2 | H30: 1 | I30: 1 | J30: 2 | K30: 6 | L30: 0/0 | M30: 1/2 | N30: 0 | O30: 0 | P30: 1 | Q30: 1 | R30: 1
A31: T. FERREIRA | B31: 3 | C31: Meneur | D31: 11'54 | E31: 0 | F31: 1 | G31: 4 | H31: 0 | I31: 3 | J31: 1 | K31: 7 | L31: 0/1 | M31: 0/1 | N31: 0 | O31: 1 | P31: 0 | Q31: 4 | R31: 1
A32: O. KAMISSOKO | B32: 5 | C32: Ailier | D32: 11'27 | E32: 0 | F32: 0 | G32: 2 | H32: 0 | I32: 1 | J32: 2 | K32: 8 | L32: 3/4 | M32: 2/3 | N32: 1 | O32: 0 | P32: 1 | Q32: 3 | R32: 0
A33: I. BERRADA | B33: 10 | C33: Meneur côté | D33: 11' | E33: 0 | F33: 1 | G33: 3 | H33: 1 | I33: 2 | J33: 2 | K33: 9 | L33: 0/3 | M33: 0/1 | N33: 0 | O33: 0 | P33: 1 | Q33: 3 | R33: 0
A34: R. HOUMADI | B34: 2 | C34: Meneur | D34: 9'34 | E34: 0 | F34: 0 | G34: 0 | H34: 0 | I34: 0 | J34: 1 | K34: 2 | L34: 0/0 | M34: 0/0 | N34: 0 | O34: 0 | P34: 1 | Q34: 1 | R34: 0
A35: F. BADAD | B35: 17 | C35: Meneur côté | D35: 9'27 | E35: 1 | F35: 0 | G35: 1 | H35: 1 | I35: 1 | J35: 0 | K35: 9 | L35: 0/3 | M35: 0/2 | N35: 0 | O35: 0 | P35: 3 | Q35: 0 | R35: 0
A36: A. HENRY | B36: 9 | C36: Ailier | D36: 9'04 | E36: 0 | F36: 0 | G36: 1 | H36: 0 | I36: 0 | J36: 0 | K36: 6 | L36: 1/3 | M36: 2/2 | N36: 0 | O36: 1 | P36: 2 | Q36: 0 | R36: 0
A37: S. AGUENGUI | B37: 4 | C37: Pivot | D37: 8'16 | E37: 0 | F37: 1 | G37: 0 | H37: 0 | I37: 1 | J37: 0 | K37: 3 | L37: 0/2 | M37: 1/1 | N37: 0 | O37: 0 | P37: 0 | Q37: 0 | R37: 0
A38: GARDIEN
A39: Gardien | B39: Temps | C39: Arrets | D39: Buts enc. | E39: Rel.F R | F39: Rel.F L | G39: Rel.D R | H39: Rel.D L | I39: % Rel. | J39: Pertes
A40: J. LUMECA | B40: 20' | C40: 8 | D40: 2 | E40: 8 | F40: 0 | G40: 2 | H40: 5 | I40: 0.66666667 | J40: 4
A41: M. VALVERDE | B41: 20' | C41: 7 | D41: 4 | E41: 13 | F41: 0 | G41: 5 | H41: 1 | I41: 0.94736842 | J41: 3
A44: FRANCE 4 – 6 PORTUGAL (France) - DEFAITE
A45: Joueur | B45: N | C45: Poste | D45: Temps | E45: Buts | F45: PD | G45: Tirs | H45: T.Cad | I45: Int. | J45: Rec. | K45: Pertes | L45: D.OFF G/T | M45: D.DEF G/T | N45: Fautes C. | O45: Fautes S. | P45: Err.T. | Q45: Pass.L. | R45: Ball.R.
A46: L. LADIRE | B46: 8 | C46: Meneur | D46: 18'30 | E46: 0 | F46: 1 | G46: 5 | H46: 2 | I46: 2 | J46: 1 | K46: 11 | L46: 1/1 | M46: 2/2 | N46: 0 | O46: 0 | P46: 4 | Q46: 2 | R46: 0
A47: L. RAHO MOUSSA | B47: 9 | C47: Ailier | D47: 18'00 | E47: 2 | F47: 0 | G47: 15 | H47: 8 | I47: 2 | J47: 1 | K47: 9 | L47: 3/4 | M47: 0/0 | N47: 2 | O47: 2 | P47: 5 | Q47: 2 | R47: 0
...

Sheet COMPARAISON
A1: COMPARAISON JOUEURS | Q1: Joueur | R1: Buts | S1: PD | T1: Tirs | U1: Tirs_cad | V1: Int | W1: Rec | X1: Pertes | Y1: D_OFF_G | Z1: D_OFF_T | AA1: D_DEF_G | AB1: D_DEF_T | AC1: Min | AD1: Matchs
Q2: L. LADIRE | R2: =IF($K$3="Stats brutes",IF($C$3="Total (tous matchs)",SUMIFS(BASE_DATA!$T:$T,BASE_DATA!$G:$G,$Q$2),SUMIFS(BASE_DATA!$T:$T,BASE_DATA!$G:$G,$Q$2,BASE_DATA!$A:$A,INDEX(PARAMS!$D$2:$D$5,MATCH($F$3,PARAMS!$C$2:$C$5,0)))),IF($K$3="Par minute jouée",IFERROR(IF($C$3="Total (tous matchs)",SUMIFS(BASE_DATA!$T:$T,BASE_DATA!$G:$G,$Q$2),SUMIFS(BASE_DATA!$T:$T,BASE_DATA!$G:$G,$Q$2,BASE_DATA!$A:$A,INDEX(PARAMS!$D$2:$D$5,MATCH($F$3,PARAMS!$C$2:$C$5,0))))/IF($C$3="Total (tous matchs)",SUMIFS(BASE_DATA!$R:$R,BASE_DATA!$G:$G,$Q$2),SUMIFS(BASE_DATA!$R:$R,BASE_DATA!$G:$G,$Q$2,BASE_DATA!$A:$A,INDEX(PARAMS!$D$2:$D$5,MATCH($F$3,PARAMS!$C$2:$C$5,0)))),0),IFERROR(IF($C$3="Total (tous matchs)",SUMIFS(BASE_DATA!$T:$T,BASE_DATA!$G:$G,$Q$2),SUMIFS(BASE_DATA!$T:$T,BASE_DATA!$G:$G,$Q$2,BASE_DATA!$A:$A,INDEX(PARAMS!$D$2:$D$5,MATCH($F$3,PARAMS!$C$2:$C$5,0))))/IF($C$3="Total (tous matchs)",SUMIFS(BASE_DATA!$R:$R,BASE_DATA!$G:$G,$Q$2),SUMIFS(BASE_DATA!$R:$R,BASE_DATA!$G:$G,$Q$2,BASE_DATA!$A:$A,INDEX(PARAMS!$D$2:$D$5,MATCH($F$3,PARAMS!$C$2:$C$5,0))))*40,0))) -> 1 | S2: =IF($K$3="Stats brutes",IF($C$3="Total (tous matchs)",SUMIFS(BASE_DATA!$U:$U,BASE_DATA!$G:$G,$Q$2),SUMIFS(BASE_DATA!$U:$U,BASE_DATA!$G:$G,$Q$2,BASE_DATA!$A:$A,INDEX(PARAMS!$D$2:$D$5,MATCH($F$3,PARAMS!$C$2:$C$5,0)))),IF($K$3="Par minute jouée",IFERROR(IF($C$3="Total (tous matchs)",SUMIFS(BASE_DATA!$U:$U,BASE_DATA!$G:$G,$Q$2),SUMIFS(BASE_DATA!$U:$U,BASE_DATA!$G:$G,$Q$2,BASE_DATA!$A:$A,INDEX(PARAMS!$D$2:$D$5,MATCH($F$3,PARAMS!$C$2:$C$5,0))))/IF($C$3="Total (tous matchs)",SUMIFS(BASE_DATA!$R:$R,BASE_DATA!$G:$G,$Q$2),SUMIFS(BASE_DATA!$R:$R,BASE_DATA!$G:$G,$Q$2,BASE_DATA!$A:$A,INDEX(PARAMS!$D$2:$D$5,MATCH($F$3,PARAMS!$C$2:$C$5,0)))),0),IFERROR(IF($C$3="Total (tous matchs)",SUMIFS(BASE_DATA!$U:$U,BASE_DATA!$G:$G,$Q$2),SUMIFS(BASE_DATA!$U:$U,BASE_DATA!$G:$G,$Q$2,BASE_DATA!$A:$A,INDEX(PARAMS!$D$2:$D$5,MATCH($F$3,PARAMS!$C$2:$C$5,0))))/IF($C$3="Total (tous matchs)",SUMIFS(BASE_DATA!$R:$R,BASE_DATA!$G:$G,$Q$2),SUMIFS(BASE_DATA!$R:$R,BASE_DATA!$G:$G,$Q$2,BASE_DATA!$A:$A,INDEX(PARAMS!$D$2:$D$5,MATCH($F$3,PARAMS!$C$2:$C$5,0))))*40,0))) -> 0 | T2: =IF($K$3="Stats brutes",IF($C$3="Total (tous matchs)",SUMIFS(BASE_DATA!$V:$V,BASE_DATA!$G:$G,$Q$2),SUMIFS(BASE_DATA!$V:$V,BASE_DATA!$G:$G,$Q$2,BASE_DATA!$A:$A,INDEX(PARAMS!$D$2:$D$5,MATCH($F$3,PARAMS!$C$2:$C$5,0)))),IF($K$3="Par minute jouée",IFERROR(IF($C$3="Total (tous matchs)",SUMIFS(BASE_DATA!$V:$V,BASE_DATA!$G:$G,$Q$2),SUMIFS(BASE_DATA!$V:$V,BASE_DATA!$G:$G,$Q$2,BASE_DATA!$A:$A,INDEX(PARAMS!$D$2:$D$5,MATCH($F$3,PARAMS!$C$2:$C$5,0))))/IF($C$3="Total (tous matchs)",SUMIFS(BASE_DATA!$R:$R,BASE_DATA!$G:$G,$Q$2),SUMIFS(BASE_DATA!$R:$R,BASE_DATA!$G:$G,$Q$2,BASE_DATA!$A:$A,INDEX(PARAMS!$D$2:$D$5,MATCH($F$3,PARAMS!$C$2:$C$5,0)))),0),IFERROR(IF($C$3="Total (tous matchs)",SUMIFS(BASE_DATA!$V:$V,BASE_DATA!$G:$G,$Q$2),SUMIFS(BASE_DATA!$V:$V,BASE_DATA!$G:$G,$Q$2,BASE_DATA!$A:$A,INDEX(PARAMS!$D$2:$D$5,MATCH($F$3,PARAMS!$C$2:$C$5,0))))/IF($C$3="Total (tous matchs)",SUMIFS(BASE_DATA!$R:$R,BASE_DATA!$G:$G,$Q$2),SUMIFS(BASE_DATA!$R:$R,BASE_DATA!$G:$G,$Q$2,BASE_DATA!$A:$A,INDEX(PARAMS!$D$2:$D$5,MATCH($F$3,PARAMS!$C$2:$C$5,0))))*40,0))) -> 4 | U2: =IF($K$3="Stats brutes",IF($C$3="Total (tous matchs)",SUMIFS(BASE_DATA!$W:$W,BASE_DATA!$G:$G,$Q$2),SUMIFS(BASE_DATA!$W:$W,BASE_DATA!$G:$G,$Q$2,BASE_DATA!$A:$A,INDEX(PARAMS!$D$2:$D$5,MATCH($F$3,PARAMS!$C$2:$C$5,0)))),IF($K$3="Par minute jouée",IFERROR(IF($C$3="Total (tous matchs)",SUMIFS(BASE_DATA!$W:$W,BASE_DATA!$G:$G,$Q$2),SUMIFS(BASE_DATA!$W:$W,BASE_DATA!$G:$G,$Q$2,BASE_DATA!$A:$A,INDEX(PARAMS!$D$2:$D$5,MATCH($F$3,PARAMS!$C$2:$C$5,0))))/IF($C$3="Total (tous matchs)",SUMIFS(BASE_DATA!$R:$R,BASE_DATA!$G:$G,$Q$2),SUMIFS(BASE_DATA!$R:$R,BASE_DATA!$G:$G,$Q$2,BASE_DATA!$A:$A,INDEX(PARAMS!$D$2:$D$5,MATCH($F$3,PARAMS!$C$2:$C$5,0)))),0),IFERROR(IF($C$3="Total (tous matchs)",SUMIFS(BASE_DATA!$W:$W,BASE_DATA!$G:$G,$Q$2),SUMIFS(BASE_DATA!$W:$W,BASE_DATA!$G:$G,$Q$2,BASE_DATA!$A:$A,INDEX(PARAMS!$D$2:$D$5,MATCH($F$3,PARAMS!$C$2:$C$5,0))))/IF($C$3="Total (tous matchs)",SUMIFS(BASE_DATA!$R:$R,BASE_DATA!$G:$G,$Q$2),SUMIFS(BASE_DATA!$R:$R,BASE_DATA!$G:$G,$Q$2,BASE_DATA!$A:$A,INDEX(PARAMS!$D$2:$D$5,MATCH($F$3,PARAMS!$C$2:$C$5,0))))*40,0))) -> 3 | V2: =IF($K$3="Stats brutes",IF($C$3="Total (tous matchs)",SUMIFS(BASE_DATA!$AN:$AN,BASE_DATA!$G:$G,$Q$2),SUMIFS(BASE_DATA!$AN:$AN,BASE_DATA!$G:$G,$Q$2,BASE_DATA!$A:$A,INDEX(PARAMS!$D$2:$D$5,MATCH($F$3,PARAMS!$C$2:$C$5,0)))),IF($K$3="Par minute jouée",IFERROR(IF($C$3="Total (tous matchs)",SUMIFS(BASE_DATA!$AN:$AN,BASE_DATA!$G:$G,$Q$2),SUMIFS(BASE_DATA!$AN:$AN,BASE_DATA!$G:$G,$Q$2,BASE_DATA!$A:$A,INDEX(PARAMS!$D$2:$D$5,MATCH($F$3,PARAMS!$C$2:$C$5,0))))/IF($C$3="Total (tous matchs)",SUMIFS(BASE_DATA!$R:$R,BASE_DATA!$G:$G,$Q$2),SUMIFS(BASE_DATA!$R:$R,BASE_DATA!$G:$G,$Q$2,BASE_DATA!$A:$A,INDEX(PARAMS!$D$2:$D$5,MATCH($F$3,PARAMS!$C$2:$C$5,0)))),0),IFERROR(IF($C$3="Total (tous matchs)",SUMIFS(BASE_DATA!$AN:$AN,BASE_DATA!$G:$G,$Q$2),SUMIFS(BASE_DATA!$AN:$AN,BASE_DATA!$G:$G,$Q$2,BASE_DATA!$A:$A,INDEX(PARAMS!$D$2:$D$5,MATCH($F$3,PARAMS!$C$2:$C$5,0))))/IF($C$3="Total (tous matchs)",SUMIFS(BASE_DATA!$R:$R,BASE_DATA!$G:$G,$Q$2),SUMIFS(BASE_DATA!$R:$R,BASE_DATA!$G:$G,$Q$2,BASE_DATA!$A:$A,INDEX(PARAMS!$D$2:$D$5,MATCH($F$3,PARAMS!$C$2:$C$5,0))))*40,0))) -> 1 | W2: =IF($K$3="Stats brutes",IF($C$3="Total (tous matchs)",SUMIFS(BASE_DATA!$AO:$AO,BASE_DATA!$G:$G,$Q$2),SUMIFS(BASE_DATA!$AO:$AO,BASE_DATA!$G:$G,$Q$2,BASE_DATA!$A:$A,INDEX(PARAMS!$D$2:$D$5,MATCH($F$3,PARAMS!$C$2:$C$5,0)))),IF($K$3="Par minute jouée",IFERROR(IF($C$3="Total (tous matchs)",SUMIFS(BASE_DATA!$AO:$AO,BASE_DATA!$G:$G,$Q$2),SUMIFS(BASE_DATA!$AO:$AO,BASE_DATA!$G:$G,$Q$2,BASE_DATA!$A:$A,INDEX(PARAMS!$D$2:$D$5,MATCH($F$3,PARAMS!$C$2:$C$5,0))))/IF($C$3="Total (tous matchs)",SUMIFS(BASE_DATA!$R:$R,BASE_DATA!$G:$G,$Q$2),SUMIFS(BASE_DATA!$R:$R,BASE_DATA!$G:$G,$Q$2,BASE_DATA!$A:$A,INDEX(PARAMS!$D$2:$D$5,MATCH($F$3,PARAMS!$C$2:$C$5,0)))),0),IFERROR(IF($C$3="Total (tous matchs)",SUMIFS(BASE_DATA!$AO:$AO,BASE_DATA!$G:$G,$Q$2),SUMIFS(BASE_DATA!$AO:$AO,BASE_DATA!$G:$G,$Q$2,BASE_DATA!$A:$A,INDEX(PARAMS!$D$2:$D$5,MATCH($F$3,PARAMS!$C$2:$C$5,0))))/IF($C$3="Total (tous matchs)",SUMIFS(BASE_DATA!$R:$R,BASE_DATA!$G:$G,$Q$2),SUMIFS(BASE_DATA!$R:$R,BASE_DATA!$G:$G,$Q$2,BASE_DATA!$A:$A,INDEX(PARAMS!$D$2:$D$5,MATCH($F$3,PARAMS!$C$2:$C$5,0))))*40,0))) -> 4 | X2: =IF($K$3="Stats brutes",IF($C$3="Total (tous matchs)",SUMIFS(BASE_DATA!$AA:$AA,BASE_DATA!$G:$G,$Q$2),SUMIFS(BASE_DATA!$AA:$AA,BASE_DATA!$G:$G,$Q$2,BASE_DATA!$A:$A,INDEX(PARAMS!$D$2:$D$5,MATCH($F$3,PARAMS!$C$2:$C$5,0)))),IF($K$3="Par minute jouée",IFERROR(IF($C$3="Total (tous matchs)",SUMIFS(BASE_DATA!$AA:$AA,BASE_DATA!$G:$G,$Q$2),SUMIFS(BASE_DATA!$AA:$AA,BASE_DATA!$G:$G,$Q$2,BASE_DATA!$A:$A,INDEX(PARAMS!$D$2:$D$5,MATCH($F$3,PARAMS!$C$2:$C$5,0))))/IF($C$3="Total (tous matchs)",SUMIFS(BASE_DATA!$R:$R,BASE_DATA!$G:$G,$Q$2),SUMIFS(BASE_DATA!$R:$R,BASE_DATA!$G:$G,$Q$2,BASE_DATA!$A:$A,INDEX(PARAMS!$D$2:$D$5,MATCH($F$3,PARAMS!$C$2:$C$5,0)))),0),IFERROR(IF($C$3="Total (tous matchs)",SUMIFS(BASE_DATA!$AA:$AA,BASE_DATA!$G:$G,$Q$2),SUMIFS(BASE_DATA!$AA:$AA,BASE_DATA!$G:$G,$Q$2,BASE_DATA!$A:$A,INDEX(PARAMS!$D$2:$D$5,MATCH($F$3,PARAMS!$C$2:$C$5,0))))/IF($C$3="Total (tous matchs)",SUMIFS(BASE_DATA!$R:$R,BASE_DATA!$G:$G,$Q$2),SUMIFS(BASE_DATA!$R:$R,BASE_DATA!$G:$G,$Q$2,BASE_DATA!$A:$A,INDEX(PARAMS!$D$2:$D$5,MATCH($F$3,PARAMS!$C$2:$C$5,0))))*40,0))) -> 5 | Y2: =IF($K$3="Stats brutes",IF($C$3="Total (tous matchs)",SUMIFS(BASE_DATA!$AH:$AH,BASE_DATA!$G:$G,$Q$2),SUMIFS(BASE_DATA!$AH:$AH,BASE_DATA!$G:$G,$Q$2,BASE_DATA!$A:$A,INDEX(PARAMS!$D$2:$D$5,MATCH($F$3,PARAMS!$C$2:$C$5,0)))),IF($K$3="Par minute jouée",IFERROR(IF($C$3="Total (tous matchs)",SUMIFS(BASE_DATA!$AH:$AH,BASE_DATA!$G:$G,$Q$2),SUMIFS(BASE_DATA!$AH:$AH,BASE_DATA!$G:$G,$Q$2,BASE_DATA!$A:$A,INDEX(PARAMS!$D$2:$D$5,MATCH($F$3,PARAMS!$C$2:$C$5,0))))/IF($C$3="Total (tous matchs)",SUMIFS(BASE_DATA!$R:$R,BASE_DATA!$G:$G,$Q$2),SUMIFS(BASE_DATA!$R:$R,BASE_DATA!$G:$G,$Q$2,BASE_DATA!$A:$A,INDEX(PARAMS!$D$2:$D$5,MATCH($F$3,PARAMS!$C$2:$C$5,0)))),0),IFERROR(IF($C$3="Total (tous matchs)",SUMIFS(BASE_DATA!$AH:$AH,BASE_DATA!$G:$G,$Q$2),SUMIFS(BASE_DATA!$AH:$AH,BASE_DATA!$G:$G,$Q$2,BASE_DATA!$A:$A,INDEX(PARAMS!$D$2:$D$5,MATCH($F$3,PARAMS!$C$2:$C$5,0))))/IF($C$3="Total (tous matchs)",SUMIFS(BASE_DATA!$R:$R,BASE_DATA!$G:$G,$Q$2),SUMIFS(BASE_DATA!$R:$R,BASE_DATA!$G:$G,$Q$2,BASE_DATA!$A:$A,INDEX(PARAMS!$D$2:$D$5,MATCH($F$3,PARAMS!$C$2:$C$5,0))))*40,0))) -> 3 | Z2: =IF($K$3="Stats brutes",IF($C$3="Total (tous matchs)",SUMIFS(BASE_DATA!$AI:$AI,BASE_DATA!$G:$G,$Q$2),SUMIFS(BASE_DATA!$AI:$AI,BASE_DATA!$G:$G,$Q$2,BASE_DATA!$A:$A,INDEX(PARAMS!$D$2:$D$5,MATCH($F$3,PARAMS!$C$2:$C$5,0)))),IF($K$3="Par minute jouée",IFERROR(IF($C$3="Total (tous matchs)",SUMIFS(BASE_DATA!$AI:$AI,BASE_DATA!$G:$G,$Q$2),SUMIFS(BASE_DATA!$AI:$AI,BASE_DATA!$G:$G,$Q$2,BASE_DATA!$A:$A,INDEX(PARAMS!$D$2:$D$5,MATCH($F$3,PARAMS!$C$2:$C$5,0))))/IF($C$3="Total (tous matchs)",SUMIFS(BASE_DATA!$R:$R,BASE_DATA!$G:$G,$Q$2),SUMIFS(BASE_DATA!$R:$R,BASE_DATA!$G:$G,$Q$2,BASE_DATA!$A:$A,INDEX(PARAMS!$D$2:$D$5,MATCH($F$3,PARAMS!$C$2:$C$5,0)))),0),IFERROR(IF($C$3="Total (tous matchs)",SUMIFS(BASE_DATA!$AI:$AI,BASE_DATA!$G:$G,$Q$2),SUMIFS(BASE_DATA!$AI:$AI,BASE_DATA!$G:$G,$Q$2,BASE_DATA!$A:$A,INDEX(PARAMS!$D$2:$D$5,MATCH($F$3,PARAMS!$C$2:$C$5,0))))/IF($C$3="Total (tous matchs)",SUMIFS(BASE_DATA!$R:$R,BASE_DATA!$G:$G,$Q$2),SUMIFS(BASE_DATA!$R:$R,BASE_DATA!$G:$G,$Q$2,BASE_DATA!$A:$A,INDEX(PARAMS!$D$2:$D$5,MATCH($F$3,PARAMS!$C$2:$C$5,0))))*40,0))) -> 4 | AA2: =IF($K$3="Stats brutes",IF($C$3="Total (tous matchs)",SUMIFS(BASE_DATA!$AJ:$AJ,BASE_DATA!$G:$G,$Q$2),SUMIFS(BASE_DATA!$AJ:$AJ,BASE_DATA!$G:$G,$Q$2,BASE_DATA!$A:$A,INDEX(PARAMS!$D$2:$D$5,MATCH($F$3,PARAMS!$C$2:$C$5,0)))),IF($K$3="Par minute jouée",IFERROR(IF($C$3="Total (tous matchs)",SUMIFS(BASE_DATA!$AJ:$AJ,BASE_DATA!$G:$G,$Q$2),SUMIFS(BASE_DATA!$AJ:$AJ,BASE_DATA!$G:$G,$Q$2,BASE_DATA!$A:$A,INDEX(PARAMS!$D$2:$D$5,MATCH($F$3,PARAMS!$C$2:$C$5,0))))/IF($C$3="Total (tous matchs)",SUMIFS(BASE_DATA!$R:$R,BASE_DATA!$G:$G,$Q$2),SUMIFS(BASE_DATA!$R:$R,BASE_DATA!$G:$G,$Q$2,BASE_DATA!$A:$A,INDEX(PARAMS!$D$2:$D$5,MATCH($F$3,PARAMS!$C$2:$C$5,0)))),0),IFERROR(IF($C$3="Total (tous matchs)",SUMIFS(BASE_DATA!$AJ:$AJ,BASE_DATA!$G:$G,$Q$2),SUMIFS(BASE_DATA!$AJ:$AJ,BASE_DATA!$G:$G,$Q$2,BASE_DATA!$A:$A,INDEX(PARAMS!$D$2:$D$5,MATCH($F$3,PARAMS!$C$2:$C$5,0))))/IF($C$3="Total (tous matchs)",SUMIFS(BASE_DATA!$R:$R,BASE_DATA!$G:$G,$Q$2),SUMIFS(BASE_DATA!$R:$R,BASE_DATA!$G:$G,$Q$2,BASE_DATA!$A:$A,INDEX(PARAMS!$D$2:$D$5,MATCH($F$3,PARAMS!$C$2:$C$5,0))))*40,0))) -> 1 | AB2: =IF($K$3="Stats brutes",IF($C$3="Total (tous matchs)",SUMIFS(BASE_DATA!$AK:$AK,BASE_DATA!$G:$G,$Q$2),SUMIFS(BASE_DATA!$AK:$AK,BASE_DATA!$G:$G,$Q$2,BASE_DATA!$A:$A,INDEX(PARAMS!$D$2:$D$5,MATCH($F$3,PARAMS!$C$2:$C$5,0)))),IF($K$3="Par minute jouée",IFERROR(IF($C$3="Total (tous matchs)",SUMIFS(BASE_DATA!$AK:$AK,BASE_DATA!$G:$G,$Q$2),SUMIFS(BASE_DATA!$AK:$AK,BASE_DATA!$G:$G,$Q$2,BASE_DATA!$A:$A,INDEX(PARAMS!$D$2:$D$5,MATCH($F$3,PARAMS!$C$2:$C$5,0))))/IF($C$3="Total (tous matchs)",SUMIFS(BASE_DATA!$R:$R,BASE_DATA!$G:$G,$Q$2),SUMIFS(BASE_DATA!$R:$R,BASE_DATA!$G:$G,$Q$2,BASE_DATA!$A:$A,INDEX(PARAMS!$D$2:$D$5,MATCH($F$3,PARAMS!$C$2:$C$5,0)))),0),IFERROR(IF($C$3="Total (tous matchs)",SUMIFS(BASE_DATA!$AK:$AK,BASE_DATA!$G:$G,$Q$2),SUMIFS(BASE_DATA!$AK:$AK,BASE_DATA!$G:$G,$Q$2,BASE_DATA!$A:$A,INDEX(PARAMS!$D$2:$D$5,MATCH($F$3,PARAMS!$C$2:$C$5,0))))/IF($C$3="Total (tous matchs)",SUMIFS(BASE_DATA!$R:$R,BASE_DATA!$G:$G,$Q$2),SUMIFS(BASE_DATA!$R:$R,BASE_DATA!$G:$G,$Q$2,BASE_DATA!$A:$A,INDEX(PARAMS!$D$2:$D$5,MATCH($F$3,PARAMS!$C$2:$C$5,0))))*40,0))) -> 3 | AC2: =IF($C$3="Total (tous matchs)",SUMIFS(BASE_DATA!$R:$R,BASE_DATA!$G:$G,$Q$2),SUMIFS(BASE_DATA!$R:$R,BASE_DATA!$G:$G,$Q$2,BASE_DATA!$A:$A,INDEX(PARAMS!$D$2:$D$5,MATCH($F$3,PARAMS!$C$2:$C$5,0)))) -> 17.5 | AD2: =IF($C$3="Total (tous matchs)",COUNTIFS(BASE_DATA!$G:$G,$Q$2),COUNTIFS(BASE_DATA!$G:$G,$Q$2,BASE_DATA!$A:$A,INDEX(PARAMS!$D$2:$D$5,MATCH($F$3,PARAMS!$C$2:$C$5,0)))) -> 1
B3: PORTÉE : | C3: Comparer 2 matchs | E3: MATCH A : | F3: Croatie - Match 1 | H3: MATCH B : | I3: Portugal - Match 2 | J3: MODE : | K3: Stats brutes | Q3: T. FERREIRA | R3: =IF($K$3="Stats brutes",IF($C$3="Total (tous matchs)",SUMIFS(BASE_DATA!$T:$T,BASE_DATA!$G:$G,$Q$3),SUMIFS(BASE_DATA!$T:$T,BASE_DATA!$G:$G,$Q$3,BASE_DATA!$A:$A,INDEX(PARAMS!$D$2:$D$5,MATCH($F$3,PARAMS!$C$2:$C$5,0)))),IF($K$3="Par minute jouée",IFERROR(IF($C$3="Total (tous matchs)",SUMIFS(BASE_DATA!$T:$T,BASE_DATA!$G:$G,$Q$3),SUMIFS(BASE_DATA!$T:$T,BASE_DATA!$G:$G,$Q$3,BASE_DATA!$A:$A,INDEX(PARAMS!$D$2:$D$5,MATCH($F$3,PARAMS!$C$2:$C$5,0))))/IF($C$3="Total (tous matchs)",SUMIFS(BASE_DATA!$R:$R,BASE_DATA!$G:$G,$Q$3),SUMIFS(BASE_DATA!$R:$R,BASE_DATA!$G:$G,$Q$3,BASE_DATA!$A:$A,INDEX(PARAMS!$D$2:$D$5,MATCH($F$3,PARAMS!$C$2:$C$5,0)))),0),IFERROR(IF($C$3="Total (tous matchs)",SUMIFS(BASE_DATA!$T:$T,BASE_DATA!$G:$G,$Q$3),SUMIFS(BASE_DATA!$T:$T,BASE_DATA!$G:$G,$Q$3,BASE_DATA!$A:$A,INDEX(PARAMS!$D$2:$D$5,MATCH($F$3,PARAMS!$C$2:$C$5,0))))/IF($C$3="Total (tous matchs)",SUMIFS(BASE_DATA!$R:$R,BASE_DATA!$G:$G,$Q$3),SUMIFS(BASE_DATA!$R:$R,BASE_DATA!$G:$G,$Q$3,BASE_DATA!$A:$A,INDEX(PARAMS!$D$2:$D$5,MATCH($F$3,PARAMS!$C$2:$C$5,0))))*40,0))) -> 0 | S3: =IF($K$3="Stats brutes",IF($C$3="Total (tous matchs)",SUMIFS(BASE_DATA!$U:$U,BASE_DATA!$G:$G,$Q$3),SUMIFS(BASE_DATA!$U:$U,BASE_DATA!$G:$G,$Q$3,BASE_DATA!$A:$A,INDEX(PARAMS!$D$2:$D$5,MATCH($F$3,PARAMS!$C$2:$C$5,0)))),IF($K$3="Par minute jouée",IFERROR(IF($C$3="Total (tous matchs)",SUMIFS(BASE_DATA!$U:$U,BASE_DATA!$G:$G,$Q$3),SUMIFS(BASE_DATA!$U:$U,BASE_DATA!$G:$G,$Q$3,BASE_DATA!$A:$A,INDEX(PARAMS!$D$2:$D$5,MATCH($F$3,PARAMS!$C$2:$C$5,0))))/IF($C$3="Total (tous matchs)",SUMIFS(BASE_DATA!$R:$R,BASE_DATA!$G:$G,$Q$3),SUMIFS(BASE_DATA!$R:$R,BASE_DATA!$G:$G,$Q$3,BASE_DATA!$A:$A,INDEX(PARAMS!$D$2:$D$5,MATCH($F$3,PARAMS!$C$2:$C$5,0)))),0),IFERROR(IF($C$3="Total (tous matchs)",SUMIFS(BASE_DATA!$U:$U,BASE_DATA!$G:$G,$Q$3),SUMIFS(BASE_DATA!$U:$U,BASE_DATA!$G:$G,$Q$3,BASE_DATA!$A:$A,INDEX(PARAMS!$D$2:$D$5,MATCH($F$3,PARAMS!$C$2:$C$5,0))))/IF($C$3="Total (tous matchs)",SUMIFS(BASE_DATA!$R:$R,BASE_DATA!$G:$G,$Q$3),SUMIFS(BASE_DATA!$R:$R,BASE_DATA!$G:$G,$Q$3,BASE_DATA!$A:$A,INDEX(PARAMS!$D$2:$D$5,MATCH($F$3,PARAMS!$C$2:$C$5,0))))*40,0))) -> 0 | T3: =IF($K$3="Stats brutes",IF($C$3="Total (tous matchs)",SUMIFS(BASE_DATA!$V:$V,BASE_DATA!$G:$G,$Q$3),SUMIFS(BASE_DATA!$V:$V,BASE_DATA!$G:$G,$Q$3,BASE_DATA!$A:$A,INDEX(PARAMS!$D$2:$D$5,MATCH($F$3,PARAMS!$C$2:$C$5,0)))),IF($K$3="Par minute jouée",IFERROR(IF($C$3="Total (tous matchs)",SUMIFS(BASE_DATA!$V:$V,BASE_DATA!$G:$G,$Q$3),SUMIFS(BASE_DATA!$V:$V,BASE_DATA!$G:$G,$Q$3,BASE_DATA!$A:$A,INDEX(PARAMS!$D$2:$D$5,MATCH($F$3,PARAMS!$C$2:$C$5,0))))/IF($C$3="Total (tous matchs)",SUMIFS(BASE_DATA!$R:$R,BASE_DATA!$G:$G,$Q$3),SUMIFS(BASE_DATA!$R:$R,BASE_DATA!$G:$G,$Q$3,BASE_DATA!$A:$A,INDEX(PARAMS!$D$2:$D$5,MATCH($F$3,PARAMS!$C$2:$C$5,0)))),0),IFERROR(IF($C$3="Total (tous matchs)",SUMIFS(BASE_DATA!$V:$V,BASE_DATA!$G:$G,$Q$3),SUMIFS(BASE_DATA!$V:$V,BASE_DATA!$G:$G,$Q$3,BASE_DATA!$A:$A,INDEX(PARAMS!$D$2:$D$5,MATCH($F$3,PARAMS!$C$2:$C$5,0))))/IF($C$3="Total (tous matchs)",SUMIFS(BASE_DATA!$R:$R,BASE_DATA!$G:$G,$Q$3),SUMIFS(BASE_DATA!$R:$R,BASE_DATA!$G:$G,$Q$3,BASE_DATA!$A:$A,INDEX(PARAMS!$D$2:$D$5,MATCH($F$3,PARAMS!$C$2:$C$5,0))))*40,0))) -> 3 | U3: =IF($K$3="Stats brutes",IF($C$3="Total (tous matchs)",SUMIFS(BASE_DATA!$W:$W,BASE_DATA!$G:$G,$Q$3),SUMIFS(BASE_DATA!$W:$W,BASE_DATA!$G:$G,$Q$3,BASE_DATA!$A:$A,INDEX(PARAMS!$D$2:$D$5,MATCH($F$3,PARAMS!$C$2:$C$5,0)))),IF($K$3="Par minute jouée",IFERROR(IF($C$3="Total (tous matchs)",SUMIFS(BASE_DATA!$W:$W,BASE_DATA!$G:$G,$Q$3),SUMIFS(BASE_DATA!$W:$W,BASE_DATA!$G:$G,$Q$3,BASE_DATA!$A:$A,INDEX(PARAMS!$D$2:$D$5,MATCH($F$3,PARAMS!$C$2:$C$5,0))))/IF($C$3="Total (tous matchs)",SUMIFS(BASE_DATA!$R:$R,BASE_DATA!$G:$G,$Q$3),SUMIFS(BASE_DATA!$R:$R,BASE_DATA!$G:$G,$Q$3,BASE_DATA!$A:$A,INDEX(PARAMS!$D$2:$D$5,MATCH($F$3,PARAMS!$C$2:$C$5,0)))),0),IFERROR(IF($C$3="Total (tous matchs)",SUMIFS(BASE_DATA!$W:$W,BASE_DATA!$G:$G,$Q$3),SUMIFS(BASE_DATA!$W:$W,BASE_DATA!$G:$G,$Q$3,BASE_DATA!$A:$A,INDEX(PARAMS!$D$2:$D$5,MATCH($F$3,PARAMS!$C$2:$C$5,0))))/IF($C$3="Total (tous matchs)",SUMIFS(BASE_DATA!$R:$R,BASE_DATA!$G:$G,$Q$3),SUMIFS(BASE_DATA!$R:$R,BASE_DATA!$G:$G,$Q$3,BASE_DATA!$A:$A,INDEX(PARAMS!$D$2:$D$5,MATCH($F$3,PARAMS!$C$2:$C$5,0))))*40,0))) -> 1 | V3: =IF($K$3="Stats brutes",IF($C$3="Total (tous matchs)",SUMIFS(BASE_DATA!$AN:$AN,BASE_DATA!$G:$G,$Q$3),SUMIFS(BASE_DATA!$AN:$AN,BASE_DATA!$G:$G,$Q$3,BASE_DATA!$A:$A,INDEX(PARAMS!$D$2:$D$5,MATCH($F$3,PARAMS!$C$2:$C$5,0)))),IF($K$3="Par minute jouée",IFERROR(IF($C$3="Total (tous matchs)",SUMIFS(BASE_DATA!$AN:$AN,BASE_DATA!$G:$G,$Q$3),SUMIFS(BASE_DATA!$AN:$AN,BASE_DATA!$G:$G,$Q$3,BASE_DATA!$A:$A,INDEX(PARAMS!$D$2:$D$5,MATCH($F$3,PARAMS!$C$2:$C$5,0))))/IF($C$3="Total (tous matchs)",SUMIFS(BASE_DATA!$R:$R,BASE_DATA!$G:$G,$Q$3),SUMIFS(BASE_DATA!$R:$R,BASE_DATA!$G:$G,$Q$3,BASE_DATA!$A:$A,INDEX(PARAMS!$D$2:$D$5,MATCH($F$3,PARAMS!$C$2:$C$5,0)))),0),IFERROR(IF($C$3="Total (tous matchs)",SUMIFS(BASE_DATA!$AN:$AN,BASE_DATA!$G:$G,$Q$3),SUMIFS(BASE_DATA!$AN:$AN,BASE_DATA!$G:$G,$Q$3,BASE_DATA!$A:$A,INDEX(PARAMS!$D$2:$D$5,MATCH($F$3,PARAMS!$C$2:$C$5,0))))/IF($C$3="Total (tous matchs)",SUMIFS(BASE_DATA!$R:$R,BASE_DATA!$G:$G,$Q$3),SUMIFS(BASE_DATA!$R:$R,BASE_DATA!$G:$G,$Q$3,BASE_DATA!$A:$A,INDEX(PARAMS!$D$2:$D$5,MATCH($F$3,PARAMS!$C$2:$C$5,0))))*40,0))) -> 2 | W3: =IF($K$3="Stats brutes",IF($C$3="Total (tous matchs)",SUMIFS(BASE_DATA!$AO:$AO,BASE_DATA!$G:$G,$Q$3),SUMIFS(BASE_DATA!$AO:$AO,BASE_DATA!$G:$G,$Q$3,BASE_DATA!$A:$A,INDEX(PARAMS!$D$2:$D$5,MATCH($F$3,PARAMS!$C$2:$C$5,0)))),IF($K$3="Par minute jouée",IFERROR(IF($C$3="Total (tous matchs)",SUMIFS(BASE_DATA!$AO:$AO,BASE_DATA!$G:$G,$Q$3),SUMIFS(BASE_DATA!$AO:$AO,BASE_DATA!$G:$G,$Q$3,BASE_DATA!$A:$A,INDEX(PARAMS!$D$2:$D$5,MATCH($F$3,PARAMS!$C$2:$C$5,0))))/IF($C$3="Total (tous matchs)",SUMIFS(BASE_DATA!$R:$R,BASE_DATA!$G:$G,$Q$3),SUMIFS(BASE_DATA!$R:$R,BASE_DATA!$G:$G,$Q$3,BASE_DATA!$A:$A,INDEX(PARAMS!$D$2:$D$5,MATCH($F$3,PARAMS!$C$2:$C$5,0)))),0),IFERROR(IF($C$3="Total (tous matchs)",SUMIFS(BASE_DATA!$AO:$AO,BASE_DATA!$G:$G,$Q$3),SUMIFS(BASE_DATA!$AO:$AO,BASE_DATA!$G:$G,$Q$3,BASE_DATA!$A:$A,INDEX(PARAMS!$D$2:$D$5,MATCH($F$3,PARAMS!$C$2:$C$5,0))))/IF($C$3="Total (tous matchs)",SUMIFS(BASE_DATA!$R:$R,BASE_DATA!$G:$G,$Q$3),SUMIFS(BASE_DATA!$R:$R,BASE_DATA!$G:$G,$Q$3,BASE_DATA!$A:$A,INDEX(PARAMS!$D$2:$D$5,MATCH($F$3,PARAMS!$C$2:$C$5,0))))*40,0))) -> 1 | X3: =IF($K$3="Stats brutes",IF($C$3="Total (tous matchs)",SUMIFS(BASE_DATA!$AA:$AA,BASE_DATA!$G:$G,$Q$3),SUMIFS(BASE_DATA!$AA:$AA,BASE_DATA!$G:$G,$Q$3,BASE_DATA!$A:$A,INDEX(PARAMS!$D$2:$D$5,MATCH($F$3,PARAMS!$C$2:$C$5,0)))),IF($K$3="Par minute jouée",IFERROR(IF($C$3="Total (tous matchs)",SUMIFS(BASE_DATA!$AA:$AA,BASE_DATA!$G:$G,$Q$3),SUMIFS(BASE_DATA!$AA:$AA,BASE_DATA!$G:$G,$Q$3,BASE_DATA!$A:$A,INDEX(PARAMS!$D$2:$D$5,MATCH($F$3,PARAMS!$C$2:$C$5,0))))/IF($C$3="Total (tous matchs)",SUMIFS(BASE_DATA!$R:$R,BASE_DATA!$G:$G,$Q$3),SUMIFS(BASE_DATA!$R:$R,BASE_DATA!$G:$G,$Q$3,BASE_DATA!$A:$A,INDEX(PARAMS!$D$2:$D$5,MATCH($F$3,PARAMS!$C$2:$C$5,0)))),0),IFERROR(IF($C$3="Total (tous matchs)",SUMIFS(BASE_DATA!$AA:$AA,BASE_DATA!$G:$G,$Q$3),SUMIFS(BASE_DATA!$AA:$AA,BASE_DATA!$G:$G,$Q$3,BASE_DATA!$A:$A,INDEX(PARAMS!$D$2:$D$5,MATCH($F$3,PARAMS!$C$2:$C$5,0))))/IF($C$3="Total (tous matchs)",SUMIFS(BASE_DATA!$R:$R,BASE_DATA!$G:$G,$Q$3),SUMIFS(BASE_DATA!$R:$R,BASE_DATA!$G:$G,$Q$3,BASE_DATA!$A:$A,INDEX(PARAMS!$D$2:$D$5,MATCH($F$3,PARAMS!$C$2:$C$5,0))))*40,0))) -> 2 | Y3: =IF($K$3="Stats brutes",IF($C$3="Total (tous matchs)",SUMIFS(BASE_DATA!$AH:$AH,BASE_DATA!$G:$G,$Q$3),SUMIFS(BASE_DATA!$AH:$AH,BASE_DATA!$G:$G,$Q$3,BASE_DATA!$A:$A,INDEX(PARAMS!$D$2:$D$5,MATCH($F$3,PARAMS!$C$2:$C$5,0)))),IF($K$3="Par minute jouée",IFERROR(IF($C$3="Total (tous matchs)",SUMIFS(BASE_DATA!$AH:$AH,BASE_DATA!$G:$G,$Q$3),SUMIFS(BASE_DATA!$AH:$AH,BASE_DATA!$G:$G,$Q$3,BASE_DATA!$A:$A,INDEX(PARAMS!$D$2:$D$5,MATCH($F$3,PARAMS!$C$2:$C$5,0))))/IF($C$3="Total (tous matchs)",SUMIFS(BASE_DATA!$R:$R,BASE_DATA!$G:$G,$Q$3),SUMIFS(BASE_DATA!$R:$R,BASE_DATA!$G:$G,$Q$3,BASE_DATA!$A:$A,INDEX(PARAMS!$D$2:$D$5,MATCH($F$3,PARAMS!$C$2:$C$5,0)))),0),IFERROR(IF($C$3="Total (tous matchs)",SUMIFS(BASE_DATA!$AH:$AH,BASE_DATA!$G:$G,$Q$3),SUMIFS(BASE_DATA!$AH:$AH,BASE_DATA!$G:$G,$Q$3,BASE_DATA!$A:$A,INDEX(PARAMS!$D$2:$D$5,MATCH($F$3,PARAMS!$C$2:$C$5,0))))/IF($C$3="Total (tous matchs)",SUMIFS(BASE_DATA!$R:$R,BASE_DATA!$G:$G,$Q$3),SUMIFS(BASE_DATA!$R:$R,BASE_DATA!$G:$G,$Q$3,BASE_DATA!$A:$A,INDEX(PARAMS!$D$2:$D$5,MATCH($F$3,PARAMS!$C$2:$C$5,0))))*40,0))) -> 1 | Z3: =IF($K$3="Stats brutes",IF($C$3="Total (tous matchs)",SUMIFS(BASE_DATA!$AI:$AI,BASE_DATA!$G:$G,$Q$3),SUMIFS(BASE_DATA!$AI:$AI,BASE_DATA!$G:$G,$Q$3,BASE_DATA!$A:$A,INDEX(PARAMS!$D$2:$D$5,MATCH($F$3,PARAMS!$C$2:$C$5,0)))),IF($K$3="Par minute jouée",IFERROR(IF($C$3="Total (tous matchs)",SUMIFS(BASE_DATA!$AI:$AI,BASE_DATA!$G:$G,$Q$3),SUMIFS(BASE_DATA!$AI:$AI,BASE_DATA!$G:$G,$Q$3,BASE_DATA!$A:$A,INDEX(PARAMS!$D$2:$D$5,MATCH($F$3,PARAMS!$C$2:$C$5,0))))/IF($C$3="Total (tous matchs)",SUMIFS(BASE_DATA!$R:$R,BASE_DATA!$G:$G,$Q$3),SUMIFS(BASE_DATA!$R:$R,BASE_DATA!$G:$G,$Q$3,BASE_DATA!$A:$A,INDEX(PARAMS!$D$2:$D$5,MATCH($F$3,PARAMS!$C$2:$C$5,0)))),0),IFERROR(IF($C$3="Total (tous matchs)",SUMIFS(BASE_DATA!$AI:$AI,BASE_DATA!$G:$G,$Q$3),SUMIFS(BASE_DATA!$AI:$AI,BASE_DATA!$G:$G,$Q$3,BASE_DATA!$A:$A,INDEX(PARAMS!$D$2:$D$5,MATCH($F$3,PARAMS!$C$2:$C$5,0))))/IF($C$3="Total (tous matchs)",SUMIFS(BASE_DATA!$R:$R,BASE_DATA!$G:$G,$Q$3),SUMIFS(BASE_DATA!$R:$R,BASE_DATA!$G:$G,$Q$3,BASE_DATA!$A:$A,INDEX(PARAMS!$D$2:$D$5,MATCH($F$3,PARAMS!$C$2:$C$5,0))))*40,0))) -> 1 | AA3: =IF($K$3="Stats brutes",IF($C$3="Total (tous matchs)",SUMIFS(BASE_DATA!$AJ:$AJ,BASE_DATA!$G:$G,$Q$3),SUMIFS(BASE_DATA!$AJ:$AJ,BASE_DATA!$G:$G,$Q$3,BASE_DATA!$A:$A,INDEX(PARAMS!$D$2:$D$5,MATCH($F$3,PARAMS!$C$2:$C$5,0)))),IF($K$3="Par minute jouée",IFERROR(IF($C$3="Total (tous matchs)",SUMIFS(BASE_DATA!$AJ:$AJ,BASE_DATA!$G:$G,$Q$3),SUMIFS(BASE_DATA!$AJ:$AJ,BASE_DATA!$G:$G,$Q$3,BASE_DATA!$A:$A,INDEX(PARAMS!$D$2:$D$5,MATCH($F$3,PARAMS!$C$2:$C$5,0))))/IF($C$3="Total (tous matchs)",SUMIFS(BASE_DATA!$R:$R,BASE_DATA!$G:$G,$Q$3),SUMIFS(BASE_DATA!$R:$R,BASE_DATA!$G:$G,$Q$3,BASE_DATA!$A:$A,INDEX(PARAMS!$D$2:$D$5,MATCH($F$3,PARAMS!$C$2:$C$5,0)))),0),IFERROR(IF($C$3="Total (tous matchs)",SUMIFS(BASE_DATA!$AJ:$AJ,BASE_DATA!$G:$G,$Q$3),SUMIFS(BASE_DATA!$AJ:$AJ,BASE_DATA!$G:$G,$Q$3,BASE_DATA!$A:$A,INDEX(PARAMS!$D$2:$D$5,MATCH($F$3,PARAMS!$C$2:$C$5,0))))/IF($C$3="Total (tous matchs)",SUMIFS(BASE_DATA!$R:$R,BASE_DATA!$G:$G,$Q$3),SUMIFS(BASE_DATA!$R:$R,BASE_DATA!$G:$G,$Q$3,BASE_DATA!$A:$A,INDEX(PARAMS!$D$2:$D$5,MATCH($F$3,PARAMS!$C$2:$C$5,0))))*40,0))) -> 0 | AB3: =IF($K$3="Stats brutes",IF($C$3="Total (tous matchs)",SUMIFS(BASE_DATA!$AK:$AK,BASE_DATA!$G:$G,$Q$3),SUMIFS(BASE_DATA!$AK:$AK,BASE_DATA!$G:$G,$Q$3,BASE_DATA!$A:$A,INDEX(PARAMS!$D$2:$D$5,MATCH($F$3,PARAMS!$C$2:$C$5,0)))),IF($K$3="Par minute jouée",IFERROR(IF($C$3="Total (tous matchs)",SUMIFS(BASE_DATA!$AK:$AK,BASE_DATA!$G:$G,$Q$3),SUMIFS(BASE_DATA!$AK:$AK,BASE_DATA!$G:$G,$Q$3,BASE_DATA!$A:$A,INDEX(PARAMS!$D$2:$D$5,MATCH($F$3,PARAMS!$C$2:$C$5,0))))/IF($C$3="Total (tous matchs)",SUMIFS(BASE_DATA!$R:$R,BASE_DATA!$G:$G,$Q$3),SUMIFS(BASE_DATA!$R:$R,BASE_DATA!$G:$G,$Q$3,BASE_DATA!$A:$A,INDEX(PARAMS!$D$2:$D$5,MATCH($F$3,PARAMS!$C$2:$C$5,0)))),0),IFERROR(IF($C$3="Total (tous matchs)",SUMIFS(BASE_DATA!$AK:$AK,BASE_DATA!$G:$G,$Q$3),SUMIFS(BASE_DATA!$AK:$AK,BASE_DATA!$G:$G,$Q$3,BASE_DATA!$A:$A,INDEX(PARAMS!$D$2:$D$5,MATCH($F$3,PARAMS!$C$2:$C$5,0))))/IF($C$3="Total (tous matchs)",SUMIFS(BASE_DATA!$R:$R,BASE_DATA!$G:$G,$Q$3),SUMIFS(BASE_DATA!$R:$R,BASE_DATA!$G:$G,$Q$3,BASE_DATA!$A:$A,INDEX(PARAMS!$D$2:$D$5,MATCH($F$3,PARAMS!$C$2:$C$5,0))))*40,0))) -> 1 | AC3: =IF($C$3="Total (tous matchs)",SUMIFS(BASE_DATA!$R:$R,BASE_DATA!$G:$G,$Q$3),SUMIFS(BASE_DATA!$R:$R,BASE_DATA!$G:$G,$Q$3,BASE_DATA!$A:$A,INDEX(PARAMS!$D$2:$D$5,MATCH($F$3,PARAMS!$C$2:$C$5,0)))) -> 11 | AD3: =IF($C$3="Total (tous matchs)",COUNTIFS(BASE_DATA!$G:$G,$Q$3),COUNTIFS(BASE_DATA!$G:$G,$Q$3,BASE_DATA!$A:$A,INDEX(PARAMS!$D$2:$D$5,MATCH($F$3,PARAMS!$C$2:$C$5,0)))) -> 1
B4: Choisissez d'abord la portée. Match B sert uniquement en mode 'Comparer 2 matchs'. | Q4: O. KAMISSOKO | R4: =IF($K$3="Stats brutes",IF($C$3="Total (tous matchs)",SUMIFS(BASE_DATA!$T:$T,BASE_DATA!$G:$G,$Q$4),SUMIFS(BASE_DATA!$T:$T,BASE_DATA!$G:$G,$Q$4,BASE_DATA!$A:$A,INDEX(PARAMS!$D$2:$D$5,MATCH($F$3,PARAMS!$C$2:$C$5,0)))),IF($K$3="Par minute jouée",IFERROR(IF($C$3="Total (tous matchs)",SUMIFS(BASE_DATA!$T:$T,BASE_DATA!$G:$G,$Q$4),SUMIFS(BASE_DATA!$T:$T,BASE_DATA!$G:$G,$Q$4,BASE_DATA!$A:$A,INDEX(PARAMS!$D$2:$D$5,MATCH($F$3,PARAMS!$C$2:$C$5,0))))/IF($C$3="Total (tous matchs)",SUMIFS(BASE_DATA!$R:$R,BASE_DATA!$G:$G,$Q$4),SUMIFS(BASE_DATA!$R:$R,BASE_DATA!$G:$G,$Q$4,BASE_DATA!$A:$A,INDEX(PARAMS!$D$2:$D$5,MATCH($F$3,PARAMS!$C$2:$C$5,0)))),0),IFERROR(IF($C$3="Total (tous matchs)",SUMIFS(BASE_DATA!$T:$T,BASE_DATA!$G:$G,$Q$4),SUMIFS(BASE_DATA!$T:$T,BASE_DATA!$G:$G,$Q$4,BASE_DATA!$A:$A,INDEX(PARAMS!$D$2:$D$5,MATCH($F$3,PARAMS!$C$2:$C$5,0))))/IF($C$3="Total (tous matchs)",SUMIFS(BASE_DATA!$R:$R,BASE_DATA!$G:$G,$Q$4),SUMIFS(BASE_DATA!$R:$R,BASE_DATA!$G:$G,$Q$4,BASE_DATA!$A:$A,INDEX(PARAMS!$D$2:$D$5,MATCH($F$3,PARAMS!$C$2:$C$5,0))))*40,0))) -> 1 | S4: =IF($K$3="Stats brutes",IF($C$3="Total (tous matchs)",SUMIFS(BASE_DATA!$U:$U,BASE_DATA!$G:$G,$Q$4),SUMIFS(BASE_DATA!$U:$U,BASE_DATA!$G:$G,$Q$4,BASE_DATA!$A:$A,INDEX(PARAMS!$D$2:$D$5,MATCH($F$3,PARAMS!$C$2:$C$5,0)))),IF($K$3="Par minute jouée",IFERROR(IF($C$3="Total (tous matchs)",SUMIFS(BASE_DATA!$U:$U,BASE_DATA!$G:$G,$Q$4),SUMIFS(BASE_DATA!$U:$U,BASE_DATA!$G:$G,$Q$4,BASE_DATA!$A:$A,INDEX(PARAMS!$D$2:$D$5,MATCH($F$3,PARAMS!$C$2:$C$5,0))))/IF($C$3="Total (tous matchs)",SUMIFS(BASE_DATA!$R:$R,BASE_DATA!$G:$G,$Q$4),SUMIFS(BASE_DATA!$R:$R,BASE_DATA!$G:$G,$Q$4,BASE_DATA!$A:$A,INDEX(PARAMS!$D$2:$D$5,MATCH($F$3,PARAMS!$C$2:$C$5,0)))),0),IFERROR(IF($C$3="Total (tous matchs)",SUMIFS(BASE_DATA!$U:$U,BASE_DATA!$G:$G,$Q$4),SUMIFS(BASE_DATA!$U:$U,BASE_DATA!$G:$G,$Q$4,BASE_DATA!$A:$A,INDEX(PARAMS!$D$2:$D$5,MATCH($F$3,PARAMS!$C$2:$C$5,0))))/IF($C$3="Total (tous matchs)",SUMIFS(BASE_DATA!$R:$R,BASE_DATA!$G:$G,$Q$4),SUMIFS(BASE_DATA!$R:$R,BASE_DATA!$G:$G,$Q$4,BASE_DATA!$A:$A,INDEX(PARAMS!$D$2:$D$5,MATCH($F$3,PARAMS!$C$2:$C$5,0))))*40,0))) -> 1 | T4: =IF($K$3="Stats brutes",IF($C$3="Total (tous matchs)",SUMIFS(BASE_DATA!$V:$V,BASE_DATA!$G:$G,$Q$4),SUMIFS(BASE_DATA!$V:$V,BASE_DATA!$G:$G,$Q$4,BASE_DATA!$A:$A,INDEX(PARAMS!$D$2:$D$5,MATCH($F$3,PARAMS!$C$2:$C$5,0)))),IF($K$3="Par minute jouée",IFERROR(IF($C$3="Total (tous matchs)",SUMIFS(BASE_DATA!$V:$V,BASE_DATA!$G:$G,$Q$4),SUMIFS(BASE_DATA!$V:$V,BASE_DATA!$G:$G,$Q$4,BASE_DATA!$A:$A,INDEX(PARAMS!$D$2:$D$5,MATCH($F$3,PARAMS!$C$2:$C$5,0))))/IF($C$3="Total (tous matchs)",SUMIFS(BASE_DATA!$R:$R,BASE_DATA!$G:$G,$Q$4),SUMIFS(BASE_DATA!$R:$R,BASE_DATA!$G:$G,$Q$4,BASE_DATA!$A:$A,INDEX(PARAMS!$D$2:$D$5,MATCH($F$3,PARAMS!$C$2:$C$5,0)))),0),IFERROR(IF($C$3="Total (tous matchs)",SUMIFS(BASE_DATA!$V:$V,BASE_DATA!$G:$G,$Q$4),SUMIFS(BASE_DATA!$V:$V,BASE_DATA!$G:$G,$Q$4,BASE_DATA!$A:$A,INDEX(PARAMS!$D$2:$D$5,MATCH($F$3,PARAMS!$C$2:$C$5,0))))/IF($C$3="Total (tous matchs)",SUMIFS(BASE_DATA!$R:$R,BASE_DATA!$G:$G,$Q$4),SUMIFS(BASE_DATA!$R:$R,BASE_DATA!$G:$G,$Q$4,BASE_DATA!$A:$A,INDEX(PARAMS!$D$2:$D$5,MATCH($F$3,PARAMS!$C$2:$C$5,0))))*40,0))) -> 1 | U4: =IF($K$3="Stats brutes",IF($C$3="Total (tous matchs)",SUMIFS(BASE_DATA!$W:$W,BASE_DATA!$G:$G,$Q$4),SUMIFS(BASE_DATA!$W:$W,BASE_DATA!$G:$G,$Q$4,BASE_DATA!$A:$A,INDEX(PARAMS!$D$2:$D$5,MATCH($F$3,PARAMS!$C$2:$C$5,0)))),IF($K$3="Par minute jouée",IFERROR(IF($C$3="Total (tous matchs)",SUMIFS(BASE_DATA!$W:$W,BASE_DATA!$G:$G,$Q$4),SUMIFS(BASE_DATA!$W:$W,BASE_DATA!$G:$G,$Q$4,BASE_DATA!$A:$A,INDEX(PARAMS!$D$2:$D$5,MATCH($F$3,PARAMS!$C$2:$C$5,0))))/IF($C$3="Total (tous matchs)",SUMIFS(BASE_DATA!$R:$R,BASE_DATA!$G:$G,$Q$4),SUMIFS(BASE_DATA!$R:$R,BASE_DATA!$G:$G,$Q$4,BASE_DATA!$A:$A,INDEX(PARAMS!$D$2:$D$5,MATCH($F$3,PARAMS!$C$2:$C$5,0)))),0),IFERROR(IF($C$3="Total (tous matchs)",SUMIFS(BASE_DATA!$W:$W,BASE_DATA!$G:$G,$Q$4),SUMIFS(BASE_DATA!$W:$W,BASE_DATA!$G:$G,$Q$4,BASE_DATA!$A:$A,INDEX(PARAMS!$D$2:$D$5,MATCH($F$3,PARAMS!$C$2:$C$5,0))))/IF($C$3="Total (tous matchs)",SUMIFS(BASE_DATA!$R:$R,BASE_DATA!$G:$G,$Q$4),SUMIFS(BASE_DATA!$R:$R,BASE_DATA!$G:$G,$Q$4,BASE_DATA!$A:$A,INDEX(PARAMS!$D$2:$D$5,MATCH($F$3,PARAMS!$C$2:$C$5,0))))*40,0))) -> 1 | V4: =IF($K$3="Stats brutes",IF($C$3="Total (tous matchs)",SUMIFS(BASE_DATA!$AN:$AN,BASE_DATA!$G:$G,$Q$4),SUMIFS(BASE_DATA!$AN:$AN,BASE_DATA!$G:$G,$Q$4,BASE_DATA!$A:$A,INDEX(PARAMS!$D$2:$D$5,MATCH($F$3,PARAMS!$C$2:$C$5,0)))),IF($K$3="Par minute jouée",IFERROR(IF($C$3="Total (tous matchs)",SUMIFS(BASE_DATA!$AN:$AN,BASE_DATA!$G:$G,$Q$4),SUMIFS(BASE_DATA!$AN:$AN,BASE_DATA!$G:$G,$Q$4,BASE_DATA!$A:$A,INDEX(PARAMS!$D$2:$D$5,MATCH($F$3,PARAMS!$C$2:$C$5,0))))/IF($C$3="Total (tous matchs)",SUMIFS(BASE_DATA!$R:$R,BASE_DATA!$G:$G,$Q$4),SUMIFS(BASE_DATA!$R:$R,BASE_DATA!$G:$G,$Q$4,BASE_DATA!$A:$A,INDEX(PARAMS!$D$2:$D$5,MATCH($F$3,PARAMS!$C$2:$C$5,0)))),0),IFERROR(IF($C$3="Total (tous matchs)",SUMIFS(BASE_DATA!$AN:$AN,BASE_DATA!$G:$G,$Q$4),SUMIFS(BASE_DATA!$AN:$AN,BASE_DATA!$G:$G,$Q$4,BASE_DATA!$A:$A,INDEX(PARAMS!$D$2:$D$5,MATCH($F$3,PARAMS!$C$2:$C$5,0))))/IF($C$3="Total (tous matchs)",SUMIFS(BASE_DATA!$R:$R,BASE_DATA!$G:$G,$Q$4),SUMIFS(BASE_DATA!$R:$R,BASE_DATA!$G:$G,$Q$4,BASE_DATA!$A:$A,INDEX(PARAMS!$D$2:$D$5,MATCH($F$3,PARAMS!$C$2:$C$5,0))))*40,0))) -> 0 | W4: =IF($K$3="Stats brutes",IF($C$3="Total (tous matchs)",SUMIFS(BASE_DATA!$AO:$AO,BASE_DATA!$G:$G,$Q$4),SUMIFS(BASE_DATA!$AO:$AO,BASE_DATA!$G:$G,$Q$4,BASE_DATA!$A:$A,INDEX(PARAMS!$D$2:$D$5,MATCH($F$3,PARAMS!$C$2:$C$5,0)))),IF($K$3="Par minute jouée",IFERROR(IF($C$3="Total (tous matchs)",SUMIFS(BASE_DATA!$AO:$AO,BASE_DATA!$G:$G,$Q$4),SUMIFS(BASE_DATA!$AO:$AO,BASE_DATA!$G:$G,$Q$4,BASE_DATA!$A:$A,INDEX(PARAMS!$D$2:$D$5,MATCH($F$3,PARAMS!$C$2:$C$5,0))))/IF($C$3="Total (tous matchs)",SUMIFS(BASE_DATA!$R:$R,BASE_DATA!$G:$G,$Q$4),SUMIFS(BASE_DATA!$R:$R,BASE_DATA!$G:$G,$Q$4,BASE_DATA!$A:$A,INDEX(PARAMS!$D$2:$D$5,MATCH($F$3,PARAMS!$C$2:$C$5,0)))),0),IFERROR(IF($C$3="Total (tous matchs)",SUMIFS(BASE_DATA!$AO:$AO,BASE_DATA!$G:$G,$Q$4),SUMIFS(BASE_DATA!$AO:$AO,BASE_DATA!$G:$G,$Q$4,BASE_DATA!$A:$A,INDEX(PARAMS!$D$2:$D$5,MATCH($F$3,PARAMS!$C$2:$C$5,0))))/IF($C$3="Total (tous matchs)",SUMIFS(BASE_DATA!$R:$R,BASE_DATA!$G:$G,$Q$4),SUMIFS(BASE_DATA!$R:$R,BASE_DATA!$G:$G,$Q$4,BASE_DATA!$A:$A,INDEX(PARAMS!$D$2:$D$5,MATCH($F$3,PARAMS!$C$2:$C$5,0))))*40,0))) -> 1 | X4: =IF($K$3="Stats brutes",IF($C$3="Total (tous matchs)",SUMIFS(BASE_DATA!$AA:$AA,BASE_DATA!$G:$G,$Q$4),SUMIFS(BASE_DATA!$AA:$AA,BASE_DATA!$G:$G,$Q$4,BASE_DATA!$A:$A,INDEX(PARAMS!$D$2:$D$5,MATCH($F$3,PARAMS!$C$2:$C$5,0)))),IF($K$3="Par minute jouée",IFERROR(IF($C$3="Total (tous matchs)",SUMIFS(BASE_DATA!$AA:$AA,BASE_DATA!$G:$G,$Q$4),SUMIFS(BASE_DATA!$AA:$AA,BASE_DATA!$G:$G,$Q$4,BASE_DATA!$A:$A,INDEX(PARAMS!$D$2:$D$5,MATCH($F$3,PARAMS!$C$2:$C$5,0))))/IF($C$3="Total (tous matchs)",SUMIFS(BASE_DATA!$R:$R,BASE_DATA!$G:$G,$Q$4),SUMIFS(BASE_DATA!$R:$R,BASE_DATA!$G:$G,$Q$4,BASE_DATA!$A:$A,INDEX(PARAMS!$D$2:$D$5,MATCH($F$3,PARAMS!$C$2:$C$5,0)))),0),IFERROR(IF($C$3="Total (tous matchs)",SUMIFS(BASE_DATA!$AA:$AA,BASE_DATA!$G:$G,$Q$4),SUMIFS(BASE_DATA!$AA:$AA,BASE_DATA!$G:$G,$Q$4,BASE_DATA!$A:$A,INDEX(PARAMS!$D$2:$D$5,MATCH($F$3,PARAMS!$C$2:$C$5,0))))/IF($C$3="Total (tous matchs)",SUMIFS(BASE_DATA!$R:$R,BASE_DATA!$G:$G,$Q$4),SUMIFS(BASE_DATA!$R:$R,BASE_DATA!$G:$G,$Q$4,BASE_DATA!$A:$A,INDEX(PARAMS!$D$2:$D$5,MATCH($F$3,PARAMS!$C$2:$C$5,0))))*40,0))) -> 8 | Y4: =IF($K$3="Stats brutes",IF($C$3="Total (tous matchs)",SUMIFS(BASE_DATA!$AH:$AH,BASE_DATA!$G:$G,$Q$4),SUMIFS(BASE_DATA!$AH:$AH,BASE_DATA!$G:$G,$Q$4,BASE_DATA!$A:$A,INDEX(PARAMS!$D$2:$D$5,MATCH($F$3,PARAMS!$C$2:$C$5,0)))),IF($K$3="Par minute jouée",IFERROR(IF($C$3="Total (tous matchs)",SUMIFS(BASE_DATA!$AH:$AH,BASE_DATA!$G:$G,$Q$4),SUMIFS(BASE_DATA!$AH:$AH,BASE_DATA!$G:$G,$Q$4,BASE_DATA!$A:$A,INDEX(PARAMS!$D$2:$D$5,MATCH($F$3,PARAMS!$C$2:$C$5,0))))/IF($C$3="Total (tous matchs)",SUMIFS(BASE_DATA!$R:$R,BASE_DATA!$G:$G,$Q$4),SUMIFS(BASE_DATA!$R:$R,BASE_DATA!$G:$G,$Q$4,BASE_DATA!$A:$A,INDEX(PARAMS!$D$2:$D$5,MATCH($F$3,PARAMS!$C$2:$C$5,0)))),0),IFERROR(IF($C$3="Total (tous matchs)",SUMIFS(BASE_DATA!$AH:$AH,BASE_DATA!$G:$G,$Q$4),SUMIFS(BASE_DATA!$AH:$AH,BASE_DATA!$G:$G,$Q$4,BASE_DATA!$A:$A,INDEX(PARAMS!$D$2:$D$5,MATCH($F$3,PARAMS!$C$2:$C$5,0))))/IF($C$3="Total (tous matchs)",SUMIFS(BASE_DATA!$R:$R,BASE_DATA!$G:$G,$Q$4),SUMIFS(BASE_DATA!$R:$R,BASE_DATA!$G:$G,$Q$4,BASE_DATA!$A:$A,INDEX(PARAMS!$D$2:$D$5,MATCH($F$3,PARAMS!$C$2:$C$5,0))))*40,0))) -> 4 | Z4: =IF($K$3="Stats brutes",IF($C$3="Total (tous matchs)",SUMIFS(BASE_DATA!$AI:$AI,BASE_DATA!$G:$G,$Q$4),SUMIFS(BASE_DATA!$AI:$AI,BASE_DATA!$G:$G,$Q$4,BASE_DATA!$A:$A,INDEX(PARAMS!$D$2:$D$5,MATCH($F$3,PARAMS!$C$2:$C$5,0)))),IF($K$3="Par minute jouée",IFERROR(IF($C$3="Total (tous matchs)",SUMIFS(BASE_DATA!$AI:$AI,BASE_DATA!$G:$G,$Q$4),SUMIFS(BASE_DATA!$AI:$AI,BASE_DATA!$G:$G,$Q$4,BASE_DATA!$A:$A,INDEX(PARAMS!$D$2:$D$5,MATCH($F$3,PARAMS!$C$2:$C$5,0))))/IF($C$3="Total (tous matchs)",SUMIFS(BASE_DATA!$R:$R,BASE_DATA!$G:$G,$Q$4),SUMIFS(BASE_DATA!$R:$R,BASE_DATA!$G:$G,$Q$4,BASE_DATA!$A:$A,INDEX(PARAMS!$D$2:$D$5,MATCH($F$3,PARAMS!$C$2:$C$5,0)))),0),IFERROR(IF($C$3="Total (tous matchs)",SUMIFS(BASE_DATA!$AI:$AI,BASE_DATA!$G:$G,$Q$4),SUMIFS(BASE_DATA!$AI:$AI,BASE_DATA!$G:$G,$Q$4,BASE_DATA!$A:$A,INDEX(PARAMS!$D$2:$D$5,MATCH($F$3,PARAMS!$C$2:$C$5,0))))/IF($C$3="Total (tous matchs)",SUMIFS(BASE_DATA!$R:$R,BASE_DATA!$G:$G,$Q$4),SUMIFS(BASE_DATA!$R:$R,BASE_DATA!$G:$G,$Q$4,BASE_DATA!$A:$A,INDEX(PARAMS!$D$2:$D$5,MATCH($F$3,PARAMS!$C$2:$C$5,0))))*40,0))) -> 9 | AA4: =IF($K$3="Stats brutes",IF($C$3="Total (tous matchs)",SUMIFS(BASE_DATA!$AJ:$AJ,BASE_DATA!$G:$G,$Q$4),SUMIFS(BASE_DATA!$AJ:$AJ,BASE_DATA!$G:$G,$Q$4,BASE_DATA!$A:$A,INDEX(PARAMS!$D$2:$D$5,MATCH($F$3,PARAMS!$C$2:$C$5,0)))),IF($K$3="Par minute jouée",IFERROR(IF($C$3="Total (tous matchs)",SUMIFS(BASE_DATA!$AJ:$AJ,BASE_DATA!$G:$G,$Q$4),SUMIFS(BASE_DATA!$AJ:$AJ,BASE_DATA!$G:$G,$Q$4,BASE_DATA!$A:$A,INDEX(PARAMS!$D$2:$D$5,MATCH($F$3,PARAMS!$C$2:$C$5,0))))/IF($C$3="Total (tous matchs)",SUMIFS(BASE_DATA!$R:$R,BASE_DATA!$G:$G,$Q$4),SUMIFS(BASE_DATA!$R:$R,BASE_DATA!$G:$G,$Q$4,BASE_DATA!$A:$A,INDEX(PARAMS!$D$2:$D$5,MATCH($F$3,PARAMS!$C$2:$C$5,0)))),0),IFERROR(IF($C$3="Total (tous matchs)",SUMIFS(BASE_DATA!$AJ:$AJ,BASE_DATA!$G:$G,$Q$4),SUMIFS(BASE_DATA!$AJ:$AJ,BASE_DATA!$G:$G,$Q$4,BASE_DATA!$A:$A,INDEX(PARAMS!$D$2:$D$5,MATCH($F$3,PARAMS!$C$2:$C$5,0))))/IF($C$3="Total (tous matchs)",SUMIFS(BASE_DATA!$R:$R,BASE_DATA!$G:$G,$Q$4),SUMIFS(BASE_DATA!$R:$R,BASE_DATA!$G:$G,$Q$4,BASE_DATA!$A:$A,INDEX(PARAMS!$D$2:$D$5,MATCH($F$3,PARAMS!$C$2:$C$5,0))))*40,0))) -> 1 | AB4: =IF($K$3="Stats brutes",IF($C$3="Total (tous matchs)",SUMIFS(BASE_DATA!$AK:$AK,BASE_DATA!$G:$G,$Q$4),SUMIFS(BASE_DATA!$AK:$AK,BASE_DATA!$G:$G,$Q$4,BASE_DATA!$A:$A,INDEX(PARAMS!$D$2:$D$5,MATCH($F$3,PARAMS!$C$2:$C$5,0)))),IF($K$3="Par minute jouée",IFERROR(IF($C$3="Total (tous matchs)",SUMIFS(BASE_DATA!$AK:$AK,BASE_DATA!$G:$G,$Q$4),SUMIFS(BASE_DATA!$AK:$AK,BASE_DATA!$G:$G,$Q$4,BASE_DATA!$A:$A,INDEX(PARAMS!$D$2:$D$5,MATCH($F$3,PARAMS!$C$2:$C$5,0))))/IF($C$3="Total (tous matchs)",SUMIFS(BASE_DATA!$R:$R,BASE_DATA!$G:$G,$Q$4),SUMIFS(BASE_DATA!$R:$R,BASE_DATA!$G:$G,$Q$4,BASE_DATA!$A:$A,INDEX(PARAMS!$D$2:$D$5,MATCH($F$3,PARAMS!$C$2:$C$5,0)))),0),IFERROR(IF($C$3="Total (tous matchs)",SUMIFS(BASE_DATA!$AK:$AK,BASE_DATA!$G:$G,$Q$4),SUMIFS(BASE_DATA!$AK:$AK,BASE_DATA!$G:$G,$Q$4,BASE_DATA!$A:$A,INDEX(PARAMS!$D$2:$D$5,MATCH($F$3,PARAMS!$C$2:$C$5,0))))/IF($C$3="Total (tous matchs)",SUMIFS(BASE_DATA!$R:$R,BASE_DATA!$G:$G,$Q$4),SUMIFS(BASE_DATA!$R:$R,BASE_DATA!$G:$G,$Q$4,BASE_DATA!$A:$A,INDEX(PARAMS!$D$2:$D$5,MATCH($F$3,PARAMS!$C$2:$C$5,0))))*40,0))) -> 1 | AC4: =IF($C$3="Total (tous matchs)",SUMIFS(BASE_DATA!$R:$R,BASE_DATA!$G:$G,$Q$4),SUMIFS(BASE_DATA!$R:$R,BASE_DATA!$G:$G,$Q$4,BASE_DATA!$A:$A,INDEX(PARAMS!$D$2:$D$5,MATCH($F$3,PARAMS!$C$2:$C$5,0)))) -> 9 | AD4: =IF($C$3="Total (tous matchs)",COUNTIFS(BASE_DATA!$G:$G,$Q$4),COUNTIFS(BASE_DATA!$G:$G,$Q$4,BASE_DATA!$A:$A,INDEX(PARAMS!$D$2:$D$5,MATCH($F$3,PARAMS!$C$2:$C$5,0)))) -> 1
